[2023-01-26 10:46:26,906][dvadmin.utils.exception.CustomExceptionHandler():54] [ERROR] Traceback (most recent call last):
  File "/Users/raviailani/Downloads/envs/lib/python3.9/site-packages/rest_framework/views.py", line 506, in dispatch
    response = handler(request, *args, **kwargs)
  File "/Users/raviailani/Downloads/envs/lib/python3.9/site-packages/rest_framework/decorators.py", line 50, in handler
    return func(*args, **kwargs)
  File "/Users/raviailani/Downloads/django-vue-admin/backend/dvadmin/sensorydata/views/sensory_data_view.py", line 62, in average_temperatures
    monthlyData[dt-1].append(i.temperature)
AttributeError: 'SensoryData' object has no attribute 'temperature'

[2023-01-26 10:46:38,278][dvadmin.utils.exception.CustomExceptionHandler():54] [ERROR] Traceback (most recent call last):
  File "/Users/raviailani/Downloads/envs/lib/python3.9/site-packages/rest_framework/views.py", line 506, in dispatch
    response = handler(request, *args, **kwargs)
  File "/Users/raviailani/Downloads/envs/lib/python3.9/site-packages/rest_framework/decorators.py", line 50, in handler
    return func(*args, **kwargs)
  File "/Users/raviailani/Downloads/django-vue-admin/backend/dvadmin/sensorydata/views/sensory_data_view.py", line 62, in average_temperatures
    monthlyData[dt-1].append(i.temperature)
AttributeError: 'SensoryData' object has no attribute 'temperature'

[2023-03-05 07:44:50,850][dvadmin.utils.exception.CustomExceptionHandler():54] [ERROR] Traceback (most recent call last):
  File "/Users/raviailani/Documents/envs/lib/python3.9/site-packages/rest_framework/views.py", line 506, in dispatch
    response = handler(request, *args, **kwargs)
  File "/Users/raviailani/Documents/envs/lib/python3.9/site-packages/rest_framework/decorators.py", line 50, in handler
    return func(*args, **kwargs)
  File "/Users/raviailani/Downloads/django-vue-admin/backend/sensory_data_app/views.py", line 280, in get_demo_chart_json
    return HttpResponse(json.loads(res), content_type="application/json")
  File "/Users/raviailani/opt/anaconda3/lib/python3.9/json/__init__.py", line 346, in loads
    return _default_decoder.decode(s)
  File "/Users/raviailani/opt/anaconda3/lib/python3.9/json/decoder.py", line 337, in decode
    obj, end = self.raw_decode(s, idx=_w(s, 0).end())
  File "/Users/raviailani/opt/anaconda3/lib/python3.9/json/decoder.py", line 353, in raw_decode
    obj, end = self.scan_once(s, idx)
json.decoder.JSONDecodeError: Expecting property name enclosed in double quotes: line 5 column 9 (char 26)

[2023-03-23 04:04:47,205][dvadmin.utils.exception.CustomExceptionHandler():54] [ERROR] Traceback (most recent call last):
  File "/Users/raviailani/opt/anaconda3/envs/envs/lib/python3.7/site-packages/django/db/backends/utils.py", line 84, in _execute
    return self.cursor.execute(sql, params)
  File "/Users/raviailani/opt/anaconda3/envs/envs/lib/python3.7/site-packages/django/db/backends/mysql/base.py", line 73, in execute
    return self.cursor.execute(query, args)
  File "/Users/raviailani/opt/anaconda3/envs/envs/lib/python3.7/site-packages/pymysql/cursors.py", line 148, in execute
    result = self._query(query)
  File "/Users/raviailani/opt/anaconda3/envs/envs/lib/python3.7/site-packages/pymysql/cursors.py", line 310, in _query
    conn.query(q)
  File "/Users/raviailani/opt/anaconda3/envs/envs/lib/python3.7/site-packages/pymysql/connections.py", line 548, in query
    self._affected_rows = self._read_query_result(unbuffered=unbuffered)
  File "/Users/raviailani/opt/anaconda3/envs/envs/lib/python3.7/site-packages/pymysql/connections.py", line 775, in _read_query_result
    result.read()
  File "/Users/raviailani/opt/anaconda3/envs/envs/lib/python3.7/site-packages/pymysql/connections.py", line 1156, in read
    first_packet = self.connection._read_packet()
  File "/Users/raviailani/opt/anaconda3/envs/envs/lib/python3.7/site-packages/pymysql/connections.py", line 725, in _read_packet
    packet.raise_for_error()
  File "/Users/raviailani/opt/anaconda3/envs/envs/lib/python3.7/site-packages/pymysql/protocol.py", line 221, in raise_for_error
    err.raise_mysql_exception(self._data)
  File "/Users/raviailani/opt/anaconda3/envs/envs/lib/python3.7/site-packages/pymysql/err.py", line 143, in raise_mysql_exception
    raise errorclass(errno, errval)
pymysql.err.OperationalError: (1054, "Unknown column 'sensory_data_app_chartconfig.entity' in 'field list'")

The above exception was the direct cause of the following exception:

Traceback (most recent call last):
  File "/Users/raviailani/opt/anaconda3/envs/envs/lib/python3.7/site-packages/rest_framework/views.py", line 506, in dispatch
    response = handler(request, *args, **kwargs)
  File "/Users/raviailani/opt/anaconda3/envs/envs/lib/python3.7/site-packages/rest_framework/decorators.py", line 50, in handler
    return func(*args, **kwargs)
  File "/Users/raviailani/Documents/django-vue-admin/backend/sensory_data_app/views.py", line 598, in get_charts_data
    for c in chart_configs:
  File "/Users/raviailani/opt/anaconda3/envs/envs/lib/python3.7/site-packages/django/db/models/query.py", line 280, in __iter__
    self._fetch_all()
  File "/Users/raviailani/opt/anaconda3/envs/envs/lib/python3.7/site-packages/django/db/models/query.py", line 1324, in _fetch_all
    self._result_cache = list(self._iterable_class(self))
  File "/Users/raviailani/opt/anaconda3/envs/envs/lib/python3.7/site-packages/django/db/models/query.py", line 51, in __iter__
    results = compiler.execute_sql(chunked_fetch=self.chunked_fetch, chunk_size=self.chunk_size)
  File "/Users/raviailani/opt/anaconda3/envs/envs/lib/python3.7/site-packages/django/db/models/sql/compiler.py", line 1175, in execute_sql
    cursor.execute(sql, params)
  File "/Users/raviailani/opt/anaconda3/envs/envs/lib/python3.7/site-packages/django/db/backends/utils.py", line 98, in execute
    return super().execute(sql, params)
  File "/Users/raviailani/opt/anaconda3/envs/envs/lib/python3.7/site-packages/django/db/backends/utils.py", line 66, in execute
    return self._execute_with_wrappers(sql, params, many=False, executor=self._execute)
  File "/Users/raviailani/opt/anaconda3/envs/envs/lib/python3.7/site-packages/django/db/backends/utils.py", line 75, in _execute_with_wrappers
    return executor(sql, params, many, context)
  File "/Users/raviailani/opt/anaconda3/envs/envs/lib/python3.7/site-packages/django/db/backends/utils.py", line 84, in _execute
    return self.cursor.execute(sql, params)
  File "/Users/raviailani/opt/anaconda3/envs/envs/lib/python3.7/site-packages/django/db/utils.py", line 90, in __exit__
    raise dj_exc_value.with_traceback(traceback) from exc_value
  File "/Users/raviailani/opt/anaconda3/envs/envs/lib/python3.7/site-packages/django/db/backends/utils.py", line 84, in _execute
    return self.cursor.execute(sql, params)
  File "/Users/raviailani/opt/anaconda3/envs/envs/lib/python3.7/site-packages/django/db/backends/mysql/base.py", line 73, in execute
    return self.cursor.execute(query, args)
  File "/Users/raviailani/opt/anaconda3/envs/envs/lib/python3.7/site-packages/pymysql/cursors.py", line 148, in execute
    result = self._query(query)
  File "/Users/raviailani/opt/anaconda3/envs/envs/lib/python3.7/site-packages/pymysql/cursors.py", line 310, in _query
    conn.query(q)
  File "/Users/raviailani/opt/anaconda3/envs/envs/lib/python3.7/site-packages/pymysql/connections.py", line 548, in query
    self._affected_rows = self._read_query_result(unbuffered=unbuffered)
  File "/Users/raviailani/opt/anaconda3/envs/envs/lib/python3.7/site-packages/pymysql/connections.py", line 775, in _read_query_result
    result.read()
  File "/Users/raviailani/opt/anaconda3/envs/envs/lib/python3.7/site-packages/pymysql/connections.py", line 1156, in read
    first_packet = self.connection._read_packet()
  File "/Users/raviailani/opt/anaconda3/envs/envs/lib/python3.7/site-packages/pymysql/connections.py", line 725, in _read_packet
    packet.raise_for_error()
  File "/Users/raviailani/opt/anaconda3/envs/envs/lib/python3.7/site-packages/pymysql/protocol.py", line 221, in raise_for_error
    err.raise_mysql_exception(self._data)
  File "/Users/raviailani/opt/anaconda3/envs/envs/lib/python3.7/site-packages/pymysql/err.py", line 143, in raise_mysql_exception
    raise errorclass(errno, errval)
django.db.utils.OperationalError: (1054, "Unknown column 'sensory_data_app_chartconfig.entity' in 'field list'")

[2023-03-23 04:11:36,170][dvadmin.utils.exception.CustomExceptionHandler():54] [ERROR] Traceback (most recent call last):
  File "/Users/raviailani/opt/anaconda3/envs/envs/lib/python3.7/site-packages/django/db/backends/utils.py", line 84, in _execute
    return self.cursor.execute(sql, params)
  File "/Users/raviailani/opt/anaconda3/envs/envs/lib/python3.7/site-packages/django/db/backends/mysql/base.py", line 73, in execute
    return self.cursor.execute(query, args)
  File "/Users/raviailani/opt/anaconda3/envs/envs/lib/python3.7/site-packages/pymysql/cursors.py", line 148, in execute
    result = self._query(query)
  File "/Users/raviailani/opt/anaconda3/envs/envs/lib/python3.7/site-packages/pymysql/cursors.py", line 310, in _query
    conn.query(q)
  File "/Users/raviailani/opt/anaconda3/envs/envs/lib/python3.7/site-packages/pymysql/connections.py", line 548, in query
    self._affected_rows = self._read_query_result(unbuffered=unbuffered)
  File "/Users/raviailani/opt/anaconda3/envs/envs/lib/python3.7/site-packages/pymysql/connections.py", line 775, in _read_query_result
    result.read()
  File "/Users/raviailani/opt/anaconda3/envs/envs/lib/python3.7/site-packages/pymysql/connections.py", line 1156, in read
    first_packet = self.connection._read_packet()
  File "/Users/raviailani/opt/anaconda3/envs/envs/lib/python3.7/site-packages/pymysql/connections.py", line 725, in _read_packet
    packet.raise_for_error()
  File "/Users/raviailani/opt/anaconda3/envs/envs/lib/python3.7/site-packages/pymysql/protocol.py", line 221, in raise_for_error
    err.raise_mysql_exception(self._data)
  File "/Users/raviailani/opt/anaconda3/envs/envs/lib/python3.7/site-packages/pymysql/err.py", line 143, in raise_mysql_exception
    raise errorclass(errno, errval)
pymysql.err.OperationalError: (1054, "Unknown column 'sensory_data_app_chartconfig.entity' in 'field list'")

The above exception was the direct cause of the following exception:

Traceback (most recent call last):
  File "/Users/raviailani/opt/anaconda3/envs/envs/lib/python3.7/site-packages/rest_framework/views.py", line 506, in dispatch
    response = handler(request, *args, **kwargs)
  File "/Users/raviailani/opt/anaconda3/envs/envs/lib/python3.7/site-packages/rest_framework/decorators.py", line 50, in handler
    return func(*args, **kwargs)
  File "/Users/raviailani/Documents/django-vue-admin/backend/sensory_data_app/views.py", line 598, in get_charts_data
    for c in chart_configs:
  File "/Users/raviailani/opt/anaconda3/envs/envs/lib/python3.7/site-packages/django/db/models/query.py", line 280, in __iter__
    self._fetch_all()
  File "/Users/raviailani/opt/anaconda3/envs/envs/lib/python3.7/site-packages/django/db/models/query.py", line 1324, in _fetch_all
    self._result_cache = list(self._iterable_class(self))
  File "/Users/raviailani/opt/anaconda3/envs/envs/lib/python3.7/site-packages/django/db/models/query.py", line 51, in __iter__
    results = compiler.execute_sql(chunked_fetch=self.chunked_fetch, chunk_size=self.chunk_size)
  File "/Users/raviailani/opt/anaconda3/envs/envs/lib/python3.7/site-packages/django/db/models/sql/compiler.py", line 1175, in execute_sql
    cursor.execute(sql, params)
  File "/Users/raviailani/opt/anaconda3/envs/envs/lib/python3.7/site-packages/django/db/backends/utils.py", line 98, in execute
    return super().execute(sql, params)
  File "/Users/raviailani/opt/anaconda3/envs/envs/lib/python3.7/site-packages/django/db/backends/utils.py", line 66, in execute
    return self._execute_with_wrappers(sql, params, many=False, executor=self._execute)
  File "/Users/raviailani/opt/anaconda3/envs/envs/lib/python3.7/site-packages/django/db/backends/utils.py", line 75, in _execute_with_wrappers
    return executor(sql, params, many, context)
  File "/Users/raviailani/opt/anaconda3/envs/envs/lib/python3.7/site-packages/django/db/backends/utils.py", line 84, in _execute
    return self.cursor.execute(sql, params)
  File "/Users/raviailani/opt/anaconda3/envs/envs/lib/python3.7/site-packages/django/db/utils.py", line 90, in __exit__
    raise dj_exc_value.with_traceback(traceback) from exc_value
  File "/Users/raviailani/opt/anaconda3/envs/envs/lib/python3.7/site-packages/django/db/backends/utils.py", line 84, in _execute
    return self.cursor.execute(sql, params)
  File "/Users/raviailani/opt/anaconda3/envs/envs/lib/python3.7/site-packages/django/db/backends/mysql/base.py", line 73, in execute
    return self.cursor.execute(query, args)
  File "/Users/raviailani/opt/anaconda3/envs/envs/lib/python3.7/site-packages/pymysql/cursors.py", line 148, in execute
    result = self._query(query)
  File "/Users/raviailani/opt/anaconda3/envs/envs/lib/python3.7/site-packages/pymysql/cursors.py", line 310, in _query
    conn.query(q)
  File "/Users/raviailani/opt/anaconda3/envs/envs/lib/python3.7/site-packages/pymysql/connections.py", line 548, in query
    self._affected_rows = self._read_query_result(unbuffered=unbuffered)
  File "/Users/raviailani/opt/anaconda3/envs/envs/lib/python3.7/site-packages/pymysql/connections.py", line 775, in _read_query_result
    result.read()
  File "/Users/raviailani/opt/anaconda3/envs/envs/lib/python3.7/site-packages/pymysql/connections.py", line 1156, in read
    first_packet = self.connection._read_packet()
  File "/Users/raviailani/opt/anaconda3/envs/envs/lib/python3.7/site-packages/pymysql/connections.py", line 725, in _read_packet
    packet.raise_for_error()
  File "/Users/raviailani/opt/anaconda3/envs/envs/lib/python3.7/site-packages/pymysql/protocol.py", line 221, in raise_for_error
    err.raise_mysql_exception(self._data)
  File "/Users/raviailani/opt/anaconda3/envs/envs/lib/python3.7/site-packages/pymysql/err.py", line 143, in raise_mysql_exception
    raise errorclass(errno, errval)
django.db.utils.OperationalError: (1054, "Unknown column 'sensory_data_app_chartconfig.entity' in 'field list'")

[2023-03-23 04:24:30,314][dvadmin.utils.exception.CustomExceptionHandler():54] [ERROR] Traceback (most recent call last):
  File "/Users/raviailani/opt/anaconda3/envs/envs/lib/python3.7/site-packages/django/db/backends/utils.py", line 84, in _execute
    return self.cursor.execute(sql, params)
  File "/Users/raviailani/opt/anaconda3/envs/envs/lib/python3.7/site-packages/django/db/backends/mysql/base.py", line 73, in execute
    return self.cursor.execute(query, args)
  File "/Users/raviailani/opt/anaconda3/envs/envs/lib/python3.7/site-packages/pymysql/cursors.py", line 148, in execute
    result = self._query(query)
  File "/Users/raviailani/opt/anaconda3/envs/envs/lib/python3.7/site-packages/pymysql/cursors.py", line 310, in _query
    conn.query(q)
  File "/Users/raviailani/opt/anaconda3/envs/envs/lib/python3.7/site-packages/pymysql/connections.py", line 548, in query
    self._affected_rows = self._read_query_result(unbuffered=unbuffered)
  File "/Users/raviailani/opt/anaconda3/envs/envs/lib/python3.7/site-packages/pymysql/connections.py", line 775, in _read_query_result
    result.read()
  File "/Users/raviailani/opt/anaconda3/envs/envs/lib/python3.7/site-packages/pymysql/connections.py", line 1156, in read
    first_packet = self.connection._read_packet()
  File "/Users/raviailani/opt/anaconda3/envs/envs/lib/python3.7/site-packages/pymysql/connections.py", line 725, in _read_packet
    packet.raise_for_error()
  File "/Users/raviailani/opt/anaconda3/envs/envs/lib/python3.7/site-packages/pymysql/protocol.py", line 221, in raise_for_error
    err.raise_mysql_exception(self._data)
  File "/Users/raviailani/opt/anaconda3/envs/envs/lib/python3.7/site-packages/pymysql/err.py", line 143, in raise_mysql_exception
    raise errorclass(errno, errval)
pymysql.err.OperationalError: (1054, "Unknown column 'sensory_data_app_chartconfig.entity' in 'field list'")

The above exception was the direct cause of the following exception:

Traceback (most recent call last):
  File "/Users/raviailani/opt/anaconda3/envs/envs/lib/python3.7/site-packages/rest_framework/views.py", line 506, in dispatch
    response = handler(request, *args, **kwargs)
  File "/Users/raviailani/opt/anaconda3/envs/envs/lib/python3.7/site-packages/rest_framework/decorators.py", line 50, in handler
    return func(*args, **kwargs)
  File "/Users/raviailani/Documents/django-vue-admin/backend/sensory_data_app/views.py", line 598, in get_charts_data
    for c in chart_configs:
  File "/Users/raviailani/opt/anaconda3/envs/envs/lib/python3.7/site-packages/django/db/models/query.py", line 280, in __iter__
    self._fetch_all()
  File "/Users/raviailani/opt/anaconda3/envs/envs/lib/python3.7/site-packages/django/db/models/query.py", line 1324, in _fetch_all
    self._result_cache = list(self._iterable_class(self))
  File "/Users/raviailani/opt/anaconda3/envs/envs/lib/python3.7/site-packages/django/db/models/query.py", line 51, in __iter__
    results = compiler.execute_sql(chunked_fetch=self.chunked_fetch, chunk_size=self.chunk_size)
  File "/Users/raviailani/opt/anaconda3/envs/envs/lib/python3.7/site-packages/django/db/models/sql/compiler.py", line 1175, in execute_sql
    cursor.execute(sql, params)
  File "/Users/raviailani/opt/anaconda3/envs/envs/lib/python3.7/site-packages/django/db/backends/utils.py", line 98, in execute
    return super().execute(sql, params)
  File "/Users/raviailani/opt/anaconda3/envs/envs/lib/python3.7/site-packages/django/db/backends/utils.py", line 66, in execute
    return self._execute_with_wrappers(sql, params, many=False, executor=self._execute)
  File "/Users/raviailani/opt/anaconda3/envs/envs/lib/python3.7/site-packages/django/db/backends/utils.py", line 75, in _execute_with_wrappers
    return executor(sql, params, many, context)
  File "/Users/raviailani/opt/anaconda3/envs/envs/lib/python3.7/site-packages/django/db/backends/utils.py", line 84, in _execute
    return self.cursor.execute(sql, params)
  File "/Users/raviailani/opt/anaconda3/envs/envs/lib/python3.7/site-packages/django/db/utils.py", line 90, in __exit__
    raise dj_exc_value.with_traceback(traceback) from exc_value
  File "/Users/raviailani/opt/anaconda3/envs/envs/lib/python3.7/site-packages/django/db/backends/utils.py", line 84, in _execute
    return self.cursor.execute(sql, params)
  File "/Users/raviailani/opt/anaconda3/envs/envs/lib/python3.7/site-packages/django/db/backends/mysql/base.py", line 73, in execute
    return self.cursor.execute(query, args)
  File "/Users/raviailani/opt/anaconda3/envs/envs/lib/python3.7/site-packages/pymysql/cursors.py", line 148, in execute
    result = self._query(query)
  File "/Users/raviailani/opt/anaconda3/envs/envs/lib/python3.7/site-packages/pymysql/cursors.py", line 310, in _query
    conn.query(q)
  File "/Users/raviailani/opt/anaconda3/envs/envs/lib/python3.7/site-packages/pymysql/connections.py", line 548, in query
    self._affected_rows = self._read_query_result(unbuffered=unbuffered)
  File "/Users/raviailani/opt/anaconda3/envs/envs/lib/python3.7/site-packages/pymysql/connections.py", line 775, in _read_query_result
    result.read()
  File "/Users/raviailani/opt/anaconda3/envs/envs/lib/python3.7/site-packages/pymysql/connections.py", line 1156, in read
    first_packet = self.connection._read_packet()
  File "/Users/raviailani/opt/anaconda3/envs/envs/lib/python3.7/site-packages/pymysql/connections.py", line 725, in _read_packet
    packet.raise_for_error()
  File "/Users/raviailani/opt/anaconda3/envs/envs/lib/python3.7/site-packages/pymysql/protocol.py", line 221, in raise_for_error
    err.raise_mysql_exception(self._data)
  File "/Users/raviailani/opt/anaconda3/envs/envs/lib/python3.7/site-packages/pymysql/err.py", line 143, in raise_mysql_exception
    raise errorclass(errno, errval)
django.db.utils.OperationalError: (1054, "Unknown column 'sensory_data_app_chartconfig.entity' in 'field list'")

[2023-03-23 04:48:30,026][dvadmin.utils.exception.CustomExceptionHandler():54] [ERROR] Traceback (most recent call last):
  File "/Users/raviailani/opt/anaconda3/envs/envs/lib/python3.7/site-packages/django/db/backends/utils.py", line 84, in _execute
    return self.cursor.execute(sql, params)
  File "/Users/raviailani/opt/anaconda3/envs/envs/lib/python3.7/site-packages/django/db/backends/mysql/base.py", line 73, in execute
    return self.cursor.execute(query, args)
  File "/Users/raviailani/opt/anaconda3/envs/envs/lib/python3.7/site-packages/pymysql/cursors.py", line 148, in execute
    result = self._query(query)
  File "/Users/raviailani/opt/anaconda3/envs/envs/lib/python3.7/site-packages/pymysql/cursors.py", line 310, in _query
    conn.query(q)
  File "/Users/raviailani/opt/anaconda3/envs/envs/lib/python3.7/site-packages/pymysql/connections.py", line 548, in query
    self._affected_rows = self._read_query_result(unbuffered=unbuffered)
  File "/Users/raviailani/opt/anaconda3/envs/envs/lib/python3.7/site-packages/pymysql/connections.py", line 775, in _read_query_result
    result.read()
  File "/Users/raviailani/opt/anaconda3/envs/envs/lib/python3.7/site-packages/pymysql/connections.py", line 1156, in read
    first_packet = self.connection._read_packet()
  File "/Users/raviailani/opt/anaconda3/envs/envs/lib/python3.7/site-packages/pymysql/connections.py", line 725, in _read_packet
    packet.raise_for_error()
  File "/Users/raviailani/opt/anaconda3/envs/envs/lib/python3.7/site-packages/pymysql/protocol.py", line 221, in raise_for_error
    err.raise_mysql_exception(self._data)
  File "/Users/raviailani/opt/anaconda3/envs/envs/lib/python3.7/site-packages/pymysql/err.py", line 143, in raise_mysql_exception
    raise errorclass(errno, errval)
pymysql.err.DataError: (1406, "Data too long for column 'entity' at row 1")

The above exception was the direct cause of the following exception:

Traceback (most recent call last):
  File "/Users/raviailani/opt/anaconda3/envs/envs/lib/python3.7/site-packages/rest_framework/views.py", line 506, in dispatch
    response = handler(request, *args, **kwargs)
  File "/Users/raviailani/Documents/django-vue-admin/backend/dvadmin/utils/viewset.py", line 75, in create
    self.perform_create(serializer)
  File "/Users/raviailani/opt/anaconda3/envs/envs/lib/python3.7/site-packages/rest_framework/mixins.py", line 24, in perform_create
    serializer.save()
  File "/Users/raviailani/Documents/django-vue-admin/backend/dvadmin/utils/serializers.py", line 62, in save
    return super().save(**kwargs)
  File "/Users/raviailani/opt/anaconda3/envs/envs/lib/python3.7/site-packages/rest_framework/serializers.py", line 205, in save
    self.instance = self.create(validated_data)
  File "/Users/raviailani/Documents/django-vue-admin/backend/dvadmin/utils/serializers.py", line 79, in create
    return super().create(validated_data)
  File "/Users/raviailani/opt/anaconda3/envs/envs/lib/python3.7/site-packages/rest_framework/serializers.py", line 939, in create
    instance = ModelClass._default_manager.create(**validated_data)
  File "/Users/raviailani/opt/anaconda3/envs/envs/lib/python3.7/site-packages/django/db/models/manager.py", line 85, in manager_method
    return getattr(self.get_queryset(), name)(*args, **kwargs)
  File "/Users/raviailani/opt/anaconda3/envs/envs/lib/python3.7/site-packages/django/db/models/query.py", line 453, in create
    obj.save(force_insert=True, using=self.db)
  File "/Users/raviailani/opt/anaconda3/envs/envs/lib/python3.7/site-packages/django/db/models/base.py", line 727, in save
    force_update=force_update, update_fields=update_fields)
  File "/Users/raviailani/opt/anaconda3/envs/envs/lib/python3.7/site-packages/django/db/models/base.py", line 765, in save_base
    force_update, using, update_fields,
  File "/Users/raviailani/opt/anaconda3/envs/envs/lib/python3.7/site-packages/django/db/models/base.py", line 868, in _save_table
    results = self._do_insert(cls._base_manager, using, fields, returning_fields, raw)
  File "/Users/raviailani/opt/anaconda3/envs/envs/lib/python3.7/site-packages/django/db/models/base.py", line 908, in _do_insert
    using=using, raw=raw,
  File "/Users/raviailani/opt/anaconda3/envs/envs/lib/python3.7/site-packages/django/db/models/manager.py", line 85, in manager_method
    return getattr(self.get_queryset(), name)(*args, **kwargs)
  File "/Users/raviailani/opt/anaconda3/envs/envs/lib/python3.7/site-packages/django/db/models/query.py", line 1270, in _insert
    return query.get_compiler(using=using).execute_sql(returning_fields)
  File "/Users/raviailani/opt/anaconda3/envs/envs/lib/python3.7/site-packages/django/db/models/sql/compiler.py", line 1416, in execute_sql
    cursor.execute(sql, params)
  File "/Users/raviailani/opt/anaconda3/envs/envs/lib/python3.7/site-packages/django/db/backends/utils.py", line 98, in execute
    return super().execute(sql, params)
  File "/Users/raviailani/opt/anaconda3/envs/envs/lib/python3.7/site-packages/django/db/backends/utils.py", line 66, in execute
    return self._execute_with_wrappers(sql, params, many=False, executor=self._execute)
  File "/Users/raviailani/opt/anaconda3/envs/envs/lib/python3.7/site-packages/django/db/backends/utils.py", line 75, in _execute_with_wrappers
    return executor(sql, params, many, context)
  File "/Users/raviailani/opt/anaconda3/envs/envs/lib/python3.7/site-packages/django/db/backends/utils.py", line 84, in _execute
    return self.cursor.execute(sql, params)
  File "/Users/raviailani/opt/anaconda3/envs/envs/lib/python3.7/site-packages/django/db/utils.py", line 90, in __exit__
    raise dj_exc_value.with_traceback(traceback) from exc_value
  File "/Users/raviailani/opt/anaconda3/envs/envs/lib/python3.7/site-packages/django/db/backends/utils.py", line 84, in _execute
    return self.cursor.execute(sql, params)
  File "/Users/raviailani/opt/anaconda3/envs/envs/lib/python3.7/site-packages/django/db/backends/mysql/base.py", line 73, in execute
    return self.cursor.execute(query, args)
  File "/Users/raviailani/opt/anaconda3/envs/envs/lib/python3.7/site-packages/pymysql/cursors.py", line 148, in execute
    result = self._query(query)
  File "/Users/raviailani/opt/anaconda3/envs/envs/lib/python3.7/site-packages/pymysql/cursors.py", line 310, in _query
    conn.query(q)
  File "/Users/raviailani/opt/anaconda3/envs/envs/lib/python3.7/site-packages/pymysql/connections.py", line 548, in query
    self._affected_rows = self._read_query_result(unbuffered=unbuffered)
  File "/Users/raviailani/opt/anaconda3/envs/envs/lib/python3.7/site-packages/pymysql/connections.py", line 775, in _read_query_result
    result.read()
  File "/Users/raviailani/opt/anaconda3/envs/envs/lib/python3.7/site-packages/pymysql/connections.py", line 1156, in read
    first_packet = self.connection._read_packet()
  File "/Users/raviailani/opt/anaconda3/envs/envs/lib/python3.7/site-packages/pymysql/connections.py", line 725, in _read_packet
    packet.raise_for_error()
  File "/Users/raviailani/opt/anaconda3/envs/envs/lib/python3.7/site-packages/pymysql/protocol.py", line 221, in raise_for_error
    err.raise_mysql_exception(self._data)
  File "/Users/raviailani/opt/anaconda3/envs/envs/lib/python3.7/site-packages/pymysql/err.py", line 143, in raise_mysql_exception
    raise errorclass(errno, errval)
django.db.utils.DataError: (1406, "Data too long for column 'entity' at row 1")

[2023-03-23 04:49:48,288][dvadmin.utils.exception.CustomExceptionHandler():54] [ERROR] Traceback (most recent call last):
  File "/Users/raviailani/opt/anaconda3/envs/envs/lib/python3.7/site-packages/rest_framework/views.py", line 506, in dispatch
    response = handler(request, *args, **kwargs)
  File "/Users/raviailani/opt/anaconda3/envs/envs/lib/python3.7/site-packages/rest_framework/decorators.py", line 50, in handler
    return func(*args, **kwargs)
  File "/Users/raviailani/Documents/django-vue-admin/backend/sensory_data_app/views.py", line 599, in get_charts_data
    if (c.data_type == "montly_average"):
AttributeError: 'ChartConfig' object has no attribute 'data_type'

[2023-03-23 04:49:58,311][dvadmin.utils.exception.CustomExceptionHandler():54] [ERROR] Traceback (most recent call last):
  File "/Users/raviailani/opt/anaconda3/envs/envs/lib/python3.7/site-packages/rest_framework/views.py", line 506, in dispatch
    response = handler(request, *args, **kwargs)
  File "/Users/raviailani/opt/anaconda3/envs/envs/lib/python3.7/site-packages/rest_framework/decorators.py", line 50, in handler
    return func(*args, **kwargs)
  File "/Users/raviailani/Documents/django-vue-admin/backend/sensory_data_app/views.py", line 599, in get_charts_data
    if (c.data_type == "montly_average"):
AttributeError: 'ChartConfig' object has no attribute 'data_type'

[2023-03-23 04:50:00,068][dvadmin.utils.exception.CustomExceptionHandler():54] [ERROR] Traceback (most recent call last):
  File "/Users/raviailani/opt/anaconda3/envs/envs/lib/python3.7/site-packages/rest_framework/views.py", line 506, in dispatch
    response = handler(request, *args, **kwargs)
  File "/Users/raviailani/opt/anaconda3/envs/envs/lib/python3.7/site-packages/rest_framework/decorators.py", line 50, in handler
    return func(*args, **kwargs)
  File "/Users/raviailani/Documents/django-vue-admin/backend/sensory_data_app/views.py", line 599, in get_charts_data
    if (c.data_type == "montly_average"):
AttributeError: 'ChartConfig' object has no attribute 'data_type'

[2023-03-23 04:51:26,653][dvadmin.utils.exception.CustomExceptionHandler():54] [ERROR] Traceback (most recent call last):
  File "/Users/raviailani/opt/anaconda3/envs/envs/lib/python3.7/site-packages/rest_framework/views.py", line 506, in dispatch
    response = handler(request, *args, **kwargs)
  File "/Users/raviailani/opt/anaconda3/envs/envs/lib/python3.7/site-packages/rest_framework/decorators.py", line 50, in handler
    return func(*args, **kwargs)
  File "/Users/raviailani/Documents/django-vue-admin/backend/sensory_data_app/views.py", line 599, in get_charts_data
    if (c.data_type == "montly_average"):
AttributeError: 'ChartConfig' object has no attribute 'data_type'

[2023-03-23 04:51:35,223][dvadmin.utils.exception.CustomExceptionHandler():54] [ERROR] Traceback (most recent call last):
  File "/Users/raviailani/opt/anaconda3/envs/envs/lib/python3.7/site-packages/rest_framework/views.py", line 506, in dispatch
    response = handler(request, *args, **kwargs)
  File "/Users/raviailani/opt/anaconda3/envs/envs/lib/python3.7/site-packages/rest_framework/decorators.py", line 50, in handler
    return func(*args, **kwargs)
  File "/Users/raviailani/Documents/django-vue-admin/backend/sensory_data_app/views.py", line 599, in get_charts_data
    if (c.data_type == "montly_average"):
AttributeError: 'ChartConfig' object has no attribute 'data_type'

[2023-03-23 04:52:25,976][dvadmin.utils.exception.CustomExceptionHandler():54] [ERROR] Traceback (most recent call last):
  File "/Users/raviailani/opt/anaconda3/envs/envs/lib/python3.7/site-packages/rest_framework/views.py", line 506, in dispatch
    response = handler(request, *args, **kwargs)
  File "/Users/raviailani/opt/anaconda3/envs/envs/lib/python3.7/site-packages/rest_framework/decorators.py", line 50, in handler
    return func(*args, **kwargs)
  File "/Users/raviailani/Documents/django-vue-admin/backend/sensory_data_app/views.py", line 599, in get_charts_data
    if (c.data_type == "montly_average"):
AttributeError: 'ChartConfig' object has no attribute 'data_type'

[2023-03-23 04:54:16,053][dvadmin.utils.exception.CustomExceptionHandler():54] [ERROR] Traceback (most recent call last):
  File "/Users/raviailani/opt/anaconda3/envs/envs/lib/python3.7/site-packages/django/db/backends/utils.py", line 84, in _execute
    return self.cursor.execute(sql, params)
  File "/Users/raviailani/opt/anaconda3/envs/envs/lib/python3.7/site-packages/django/db/backends/mysql/base.py", line 73, in execute
    return self.cursor.execute(query, args)
  File "/Users/raviailani/opt/anaconda3/envs/envs/lib/python3.7/site-packages/pymysql/cursors.py", line 148, in execute
    result = self._query(query)
  File "/Users/raviailani/opt/anaconda3/envs/envs/lib/python3.7/site-packages/pymysql/cursors.py", line 310, in _query
    conn.query(q)
  File "/Users/raviailani/opt/anaconda3/envs/envs/lib/python3.7/site-packages/pymysql/connections.py", line 548, in query
    self._affected_rows = self._read_query_result(unbuffered=unbuffered)
  File "/Users/raviailani/opt/anaconda3/envs/envs/lib/python3.7/site-packages/pymysql/connections.py", line 775, in _read_query_result
    result.read()
  File "/Users/raviailani/opt/anaconda3/envs/envs/lib/python3.7/site-packages/pymysql/connections.py", line 1156, in read
    first_packet = self.connection._read_packet()
  File "/Users/raviailani/opt/anaconda3/envs/envs/lib/python3.7/site-packages/pymysql/connections.py", line 725, in _read_packet
    packet.raise_for_error()
  File "/Users/raviailani/opt/anaconda3/envs/envs/lib/python3.7/site-packages/pymysql/protocol.py", line 221, in raise_for_error
    err.raise_mysql_exception(self._data)
  File "/Users/raviailani/opt/anaconda3/envs/envs/lib/python3.7/site-packages/pymysql/err.py", line 143, in raise_mysql_exception
    raise errorclass(errno, errval)
pymysql.err.OperationalError: (1054, "Unknown column 'sensory_data_app_chartconfig.function_type' in 'field list'")

The above exception was the direct cause of the following exception:

Traceback (most recent call last):
  File "/Users/raviailani/opt/anaconda3/envs/envs/lib/python3.7/site-packages/rest_framework/views.py", line 506, in dispatch
    response = handler(request, *args, **kwargs)
  File "/Users/raviailani/Documents/django-vue-admin/backend/dvadmin/utils/viewset.py", line 106, in destroy
    instance = self.get_object()
  File "/Users/raviailani/opt/anaconda3/envs/envs/lib/python3.7/site-packages/rest_framework/generics.py", line 96, in get_object
    obj = get_object_or_404(queryset, **filter_kwargs)
  File "/Users/raviailani/opt/anaconda3/envs/envs/lib/python3.7/site-packages/rest_framework/generics.py", line 19, in get_object_or_404
    return _get_object_or_404(queryset, *filter_args, **filter_kwargs)
  File "/Users/raviailani/opt/anaconda3/envs/envs/lib/python3.7/site-packages/django/shortcuts.py", line 76, in get_object_or_404
    return queryset.get(*args, **kwargs)
  File "/Users/raviailani/opt/anaconda3/envs/envs/lib/python3.7/site-packages/django/db/models/query.py", line 431, in get
    num = len(clone)
  File "/Users/raviailani/opt/anaconda3/envs/envs/lib/python3.7/site-packages/django/db/models/query.py", line 262, in __len__
    self._fetch_all()
  File "/Users/raviailani/opt/anaconda3/envs/envs/lib/python3.7/site-packages/django/db/models/query.py", line 1324, in _fetch_all
    self._result_cache = list(self._iterable_class(self))
  File "/Users/raviailani/opt/anaconda3/envs/envs/lib/python3.7/site-packages/django/db/models/query.py", line 51, in __iter__
    results = compiler.execute_sql(chunked_fetch=self.chunked_fetch, chunk_size=self.chunk_size)
  File "/Users/raviailani/opt/anaconda3/envs/envs/lib/python3.7/site-packages/django/db/models/sql/compiler.py", line 1175, in execute_sql
    cursor.execute(sql, params)
  File "/Users/raviailani/opt/anaconda3/envs/envs/lib/python3.7/site-packages/django/db/backends/utils.py", line 98, in execute
    return super().execute(sql, params)
  File "/Users/raviailani/opt/anaconda3/envs/envs/lib/python3.7/site-packages/django/db/backends/utils.py", line 66, in execute
    return self._execute_with_wrappers(sql, params, many=False, executor=self._execute)
  File "/Users/raviailani/opt/anaconda3/envs/envs/lib/python3.7/site-packages/django/db/backends/utils.py", line 75, in _execute_with_wrappers
    return executor(sql, params, many, context)
  File "/Users/raviailani/opt/anaconda3/envs/envs/lib/python3.7/site-packages/django/db/backends/utils.py", line 84, in _execute
    return self.cursor.execute(sql, params)
  File "/Users/raviailani/opt/anaconda3/envs/envs/lib/python3.7/site-packages/django/db/utils.py", line 90, in __exit__
    raise dj_exc_value.with_traceback(traceback) from exc_value
  File "/Users/raviailani/opt/anaconda3/envs/envs/lib/python3.7/site-packages/django/db/backends/utils.py", line 84, in _execute
    return self.cursor.execute(sql, params)
  File "/Users/raviailani/opt/anaconda3/envs/envs/lib/python3.7/site-packages/django/db/backends/mysql/base.py", line 73, in execute
    return self.cursor.execute(query, args)
  File "/Users/raviailani/opt/anaconda3/envs/envs/lib/python3.7/site-packages/pymysql/cursors.py", line 148, in execute
    result = self._query(query)
  File "/Users/raviailani/opt/anaconda3/envs/envs/lib/python3.7/site-packages/pymysql/cursors.py", line 310, in _query
    conn.query(q)
  File "/Users/raviailani/opt/anaconda3/envs/envs/lib/python3.7/site-packages/pymysql/connections.py", line 548, in query
    self._affected_rows = self._read_query_result(unbuffered=unbuffered)
  File "/Users/raviailani/opt/anaconda3/envs/envs/lib/python3.7/site-packages/pymysql/connections.py", line 775, in _read_query_result
    result.read()
  File "/Users/raviailani/opt/anaconda3/envs/envs/lib/python3.7/site-packages/pymysql/connections.py", line 1156, in read
    first_packet = self.connection._read_packet()
  File "/Users/raviailani/opt/anaconda3/envs/envs/lib/python3.7/site-packages/pymysql/connections.py", line 725, in _read_packet
    packet.raise_for_error()
  File "/Users/raviailani/opt/anaconda3/envs/envs/lib/python3.7/site-packages/pymysql/protocol.py", line 221, in raise_for_error
    err.raise_mysql_exception(self._data)
  File "/Users/raviailani/opt/anaconda3/envs/envs/lib/python3.7/site-packages/pymysql/err.py", line 143, in raise_mysql_exception
    raise errorclass(errno, errval)
django.db.utils.OperationalError: (1054, "Unknown column 'sensory_data_app_chartconfig.function_type' in 'field list'")

[2023-03-23 04:56:52,202][dvadmin.utils.exception.CustomExceptionHandler():54] [ERROR] Traceback (most recent call last):
  File "/Users/raviailani/opt/anaconda3/envs/envs/lib/python3.7/site-packages/rest_framework/views.py", line 506, in dispatch
    response = handler(request, *args, **kwargs)
  File "/Users/raviailani/opt/anaconda3/envs/envs/lib/python3.7/site-packages/rest_framework/decorators.py", line 50, in handler
    return func(*args, **kwargs)
  File "/Users/raviailani/Documents/django-vue-admin/backend/sensory_data_app/views.py", line 602, in get_charts_data
    data = get_average_monthly_within_range(data_objects, c.entity)
  File "/Users/raviailani/Documents/django-vue-admin/backend/sensory_data_app/views.py", line 643, in get_average_monthly_within_range
    (months[i], str(sum(monthlyData[11]) / (len(monthlyData[11])-1))))
ZeroDivisionError: division by zero

[2023-03-23 05:32:23,266][dvadmin.utils.exception.CustomExceptionHandler():54] [ERROR] Traceback (most recent call last):
  File "/Users/raviailani/opt/anaconda3/envs/envs/lib/python3.7/site-packages/rest_framework/views.py", line 506, in dispatch
    response = handler(request, *args, **kwargs)
  File "/Users/raviailani/opt/anaconda3/envs/envs/lib/python3.7/site-packages/rest_framework/decorators.py", line 50, in handler
    return func(*args, **kwargs)
  File "/Users/raviailani/Documents/django-vue-admin/backend/sensory_data_app/views.py", line 598, in get_charts_data
    chart_configs = ChartConfig.objects.filter(exposed=True)
  File "/Users/raviailani/opt/anaconda3/envs/envs/lib/python3.7/site-packages/django/db/models/manager.py", line 85, in manager_method
    return getattr(self.get_queryset(), name)(*args, **kwargs)
  File "/Users/raviailani/opt/anaconda3/envs/envs/lib/python3.7/site-packages/django/db/models/query.py", line 941, in filter
    return self._filter_or_exclude(False, args, kwargs)
  File "/Users/raviailani/opt/anaconda3/envs/envs/lib/python3.7/site-packages/django/db/models/query.py", line 961, in _filter_or_exclude
    clone._filter_or_exclude_inplace(negate, args, kwargs)
  File "/Users/raviailani/opt/anaconda3/envs/envs/lib/python3.7/site-packages/django/db/models/query.py", line 968, in _filter_or_exclude_inplace
    self._query.add_q(Q(*args, **kwargs))
  File "/Users/raviailani/opt/anaconda3/envs/envs/lib/python3.7/site-packages/django/db/models/sql/query.py", line 1391, in add_q
    clause, _ = self._add_q(q_object, self.used_aliases)
  File "/Users/raviailani/opt/anaconda3/envs/envs/lib/python3.7/site-packages/django/db/models/sql/query.py", line 1413, in _add_q
    split_subq=split_subq, check_filterable=check_filterable,
  File "/Users/raviailani/opt/anaconda3/envs/envs/lib/python3.7/site-packages/django/db/models/sql/query.py", line 1284, in build_filter
    lookups, parts, reffed_expression = self.solve_lookup_type(arg)
  File "/Users/raviailani/opt/anaconda3/envs/envs/lib/python3.7/site-packages/django/db/models/sql/query.py", line 1110, in solve_lookup_type
    _, field, _, lookup_parts = self.names_to_path(lookup_splitted, self.get_meta())
  File "/Users/raviailani/opt/anaconda3/envs/envs/lib/python3.7/site-packages/django/db/models/sql/query.py", line 1538, in names_to_path
    "Choices are: %s" % (name, ", ".join(available)))
django.core.exceptions.FieldError: Cannot resolve keyword 'exposed' into field. Choices are: create_datetime, creator, creator_id, dept_belong_id, description, entity, function_type, id, modifier, public_exposed, title, type, update_datetime

[2023-03-23 05:52:01,861][dvadmin.utils.exception.CustomExceptionHandler():54] [ERROR] Traceback (most recent call last):
  File "/Users/raviailani/opt/anaconda3/envs/envs/lib/python3.7/site-packages/rest_framework/views.py", line 506, in dispatch
    response = handler(request, *args, **kwargs)
  File "/Users/raviailani/opt/anaconda3/envs/envs/lib/python3.7/site-packages/rest_framework/decorators.py", line 50, in handler
    return func(*args, **kwargs)
  File "/Users/raviailani/Documents/django-vue-admin/backend/sensory_data_app/views.py", line 623, in get_charts_data
    data = get_min_of_month(data_objects, c.entity)
  File "/Users/raviailani/Documents/django-vue-admin/backend/sensory_data_app/views.py", line 717, in get_min_of_month
    (months[i], str(min(monthlyData[i]))))
ValueError: min() arg is an empty sequence

[2023-03-23 05:53:25,520][dvadmin.utils.exception.CustomExceptionHandler():54] [ERROR] Traceback (most recent call last):
  File "/Users/raviailani/opt/anaconda3/envs/envs/lib/python3.7/site-packages/rest_framework/views.py", line 506, in dispatch
    response = handler(request, *args, **kwargs)
  File "/Users/raviailani/opt/anaconda3/envs/envs/lib/python3.7/site-packages/rest_framework/decorators.py", line 50, in handler
    return func(*args, **kwargs)
  File "/Users/raviailani/Documents/django-vue-admin/backend/sensory_data_app/views.py", line 623, in get_charts_data
    data = get_min_of_month(data_objects, c.entity)
  File "/Users/raviailani/Documents/django-vue-admin/backend/sensory_data_app/views.py", line 719, in get_min_of_month
    (months[i], str(min(monthlyData[i]))))
ValueError: min() arg is an empty sequence

[2023-03-23 05:53:27,608][dvadmin.utils.exception.CustomExceptionHandler():54] [ERROR] Traceback (most recent call last):
  File "/Users/raviailani/opt/anaconda3/envs/envs/lib/python3.7/site-packages/rest_framework/views.py", line 506, in dispatch
    response = handler(request, *args, **kwargs)
  File "/Users/raviailani/opt/anaconda3/envs/envs/lib/python3.7/site-packages/rest_framework/decorators.py", line 50, in handler
    return func(*args, **kwargs)
  File "/Users/raviailani/Documents/django-vue-admin/backend/sensory_data_app/views.py", line 623, in get_charts_data
    data = get_min_of_month(data_objects, c.entity)
  File "/Users/raviailani/Documents/django-vue-admin/backend/sensory_data_app/views.py", line 719, in get_min_of_month
    (months[i], str(min(monthlyData[i]))))
ValueError: min() arg is an empty sequence

[2023-03-23 05:54:29,362][dvadmin.utils.exception.CustomExceptionHandler():54] [ERROR] Traceback (most recent call last):
  File "/Users/raviailani/opt/anaconda3/envs/envs/lib/python3.7/site-packages/rest_framework/views.py", line 506, in dispatch
    response = handler(request, *args, **kwargs)
  File "/Users/raviailani/opt/anaconda3/envs/envs/lib/python3.7/site-packages/rest_framework/decorators.py", line 50, in handler
    return func(*args, **kwargs)
  File "/Users/raviailani/Documents/django-vue-admin/backend/sensory_data_app/views.py", line 623, in get_charts_data
    data = get_min_of_month(data_objects, c.entity)
  File "/Users/raviailani/Documents/django-vue-admin/backend/sensory_data_app/views.py", line 719, in get_min_of_month
    (months[i], str(min(monthlyData[i]))))
ValueError: min() arg is an empty sequence

[2023-03-23 05:54:31,331][dvadmin.utils.exception.CustomExceptionHandler():54] [ERROR] Traceback (most recent call last):
  File "/Users/raviailani/opt/anaconda3/envs/envs/lib/python3.7/site-packages/rest_framework/views.py", line 506, in dispatch
    response = handler(request, *args, **kwargs)
  File "/Users/raviailani/opt/anaconda3/envs/envs/lib/python3.7/site-packages/rest_framework/decorators.py", line 50, in handler
    return func(*args, **kwargs)
  File "/Users/raviailani/Documents/django-vue-admin/backend/sensory_data_app/views.py", line 623, in get_charts_data
    data = get_min_of_month(data_objects, c.entity)
  File "/Users/raviailani/Documents/django-vue-admin/backend/sensory_data_app/views.py", line 719, in get_min_of_month
    (months[i], str(min(monthlyData[i]))))
ValueError: min() arg is an empty sequence

[2023-04-02 13:36:30,526][dvadmin.utils.exception.CustomExceptionHandler():54] [ERROR] Traceback (most recent call last):
  File "/Users/raviailani/Documents/envs/lib/python3.9/site-packages/rest_framework/views.py", line 506, in dispatch
    response = handler(request, *args, **kwargs)
  File "/Users/raviailani/Documents/envs/lib/python3.9/site-packages/rest_framework/decorators.py", line 50, in handler
    return func(*args, **kwargs)
  File "/Users/raviailani/Documents/django-vue-admin/backend/sensory_data_app/views.py", line 206, in get_charts_data
    data = get_plain_data_within_range(c.start_date,c.end_date, c.entity)
  File "/Users/raviailani/Documents/django-vue-admin/backend/sensory_data_app/views.py", line 291, in get_plain_data_within_range
    res.append((data['date_recorded'],data[entity]))
TypeError: 'SensoryData' object is not subscriptable

[2023-04-02 13:43:12,322][dvadmin.utils.exception.CustomExceptionHandler():54] [ERROR] Traceback (most recent call last):
  File "/Users/raviailani/Documents/envs/lib/python3.9/site-packages/django/db/models/sql/query.py", line 1930, in add_fields
    join_info = self.setup_joins(name.split(LOOKUP_SEP), opts, alias, allow_many=allow_m2m)
  File "/Users/raviailani/Documents/envs/lib/python3.9/site-packages/django/db/models/sql/query.py", line 1623, in setup_joins
    path, final_field, targets, rest = self.names_to_path(
  File "/Users/raviailani/Documents/envs/lib/python3.9/site-packages/django/db/models/sql/query.py", line 1537, in names_to_path
    raise FieldError("Cannot resolve keyword '%s' into field. "
django.core.exceptions.FieldError: Cannot resolve keyword 'entity_value' into field. Choices are: create_datetime, creator, creator_id, date_recorded, dept_belong_id, description, dissolved_oxygen, id, modifier, ph, salinity, sea_water_temperature_c, update_datetime

During handling of the above exception, another exception occurred:

Traceback (most recent call last):
  File "/Users/raviailani/Documents/envs/lib/python3.9/site-packages/rest_framework/views.py", line 506, in dispatch
    response = handler(request, *args, **kwargs)
  File "/Users/raviailani/Documents/envs/lib/python3.9/site-packages/rest_framework/decorators.py", line 50, in handler
    return func(*args, **kwargs)
  File "/Users/raviailani/Documents/django-vue-admin/backend/sensory_data_app/views.py", line 204, in get_charts_data
    data = get_plain_data_within_range(
  File "/Users/raviailani/Documents/django-vue-admin/backend/sensory_data_app/views.py", line 288, in get_plain_data_within_range
    records = SensoryData.objects.filter(
  File "/Users/raviailani/Documents/envs/lib/python3.9/site-packages/django/db/models/query.py", line 840, in values
    clone = self._values(*fields, **expressions)
  File "/Users/raviailani/Documents/envs/lib/python3.9/site-packages/django/db/models/query.py", line 835, in _values
    clone.query.set_values(fields)
  File "/Users/raviailani/Documents/envs/lib/python3.9/site-packages/django/db/models/sql/query.py", line 2246, in set_values
    self.add_fields(field_names, True)
  File "/Users/raviailani/Documents/envs/lib/python3.9/site-packages/django/db/models/sql/query.py", line 1957, in add_fields
    raise FieldError("Cannot resolve keyword %r into field. "
django.core.exceptions.FieldError: Cannot resolve keyword 'entity_value' into field. Choices are: create_datetime, creator, creator_id, date_recorded, dept_belong_id, description, dissolved_oxygen, id, modifier, ph, salinity, sea_water_temperature_c, update_datetime

[2023-04-02 13:43:23,568][dvadmin.utils.exception.CustomExceptionHandler():54] [ERROR] Traceback (most recent call last):
  File "/Users/raviailani/Documents/envs/lib/python3.9/site-packages/django/db/models/sql/query.py", line 1930, in add_fields
    join_info = self.setup_joins(name.split(LOOKUP_SEP), opts, alias, allow_many=allow_m2m)
  File "/Users/raviailani/Documents/envs/lib/python3.9/site-packages/django/db/models/sql/query.py", line 1623, in setup_joins
    path, final_field, targets, rest = self.names_to_path(
  File "/Users/raviailani/Documents/envs/lib/python3.9/site-packages/django/db/models/sql/query.py", line 1537, in names_to_path
    raise FieldError("Cannot resolve keyword '%s' into field. "
django.core.exceptions.FieldError: Cannot resolve keyword 'entity_value' into field. Choices are: create_datetime, creator, creator_id, date_recorded, dept_belong_id, description, dissolved_oxygen, id, modifier, ph, salinity, sea_water_temperature_c, update_datetime

During handling of the above exception, another exception occurred:

Traceback (most recent call last):
  File "/Users/raviailani/Documents/envs/lib/python3.9/site-packages/rest_framework/views.py", line 506, in dispatch
    response = handler(request, *args, **kwargs)
  File "/Users/raviailani/Documents/envs/lib/python3.9/site-packages/rest_framework/decorators.py", line 50, in handler
    return func(*args, **kwargs)
  File "/Users/raviailani/Documents/django-vue-admin/backend/sensory_data_app/views.py", line 204, in get_charts_data
    data = get_plain_data_within_range(
  File "/Users/raviailani/Documents/django-vue-admin/backend/sensory_data_app/views.py", line 288, in get_plain_data_within_range
    records = SensoryData.objects.filter(
  File "/Users/raviailani/Documents/envs/lib/python3.9/site-packages/django/db/models/query.py", line 840, in values
    clone = self._values(*fields, **expressions)
  File "/Users/raviailani/Documents/envs/lib/python3.9/site-packages/django/db/models/query.py", line 835, in _values
    clone.query.set_values(fields)
  File "/Users/raviailani/Documents/envs/lib/python3.9/site-packages/django/db/models/sql/query.py", line 2246, in set_values
    self.add_fields(field_names, True)
  File "/Users/raviailani/Documents/envs/lib/python3.9/site-packages/django/db/models/sql/query.py", line 1957, in add_fields
    raise FieldError("Cannot resolve keyword %r into field. "
django.core.exceptions.FieldError: Cannot resolve keyword 'entity_value' into field. Choices are: create_datetime, creator, creator_id, date_recorded, dept_belong_id, description, dissolved_oxygen, id, modifier, ph, salinity, sea_water_temperature_c, update_datetime

[2023-04-02 13:44:47,520][dvadmin.utils.exception.CustomExceptionHandler():54] [ERROR] Traceback (most recent call last):
  File "/Users/raviailani/Documents/envs/lib/python3.9/site-packages/django/db/models/sql/query.py", line 1930, in add_fields
    join_info = self.setup_joins(name.split(LOOKUP_SEP), opts, alias, allow_many=allow_m2m)
  File "/Users/raviailani/Documents/envs/lib/python3.9/site-packages/django/db/models/sql/query.py", line 1623, in setup_joins
    path, final_field, targets, rest = self.names_to_path(
  File "/Users/raviailani/Documents/envs/lib/python3.9/site-packages/django/db/models/sql/query.py", line 1537, in names_to_path
    raise FieldError("Cannot resolve keyword '%s' into field. "
django.core.exceptions.FieldError: Cannot resolve keyword 'entity_value' into field. Choices are: create_datetime, creator, creator_id, date_recorded, dept_belong_id, description, dissolved_oxygen, id, modifier, ph, salinity, sea_water_temperature_c, update_datetime

During handling of the above exception, another exception occurred:

Traceback (most recent call last):
  File "/Users/raviailani/Documents/envs/lib/python3.9/site-packages/rest_framework/views.py", line 506, in dispatch
    response = handler(request, *args, **kwargs)
  File "/Users/raviailani/Documents/envs/lib/python3.9/site-packages/rest_framework/decorators.py", line 50, in handler
    return func(*args, **kwargs)
  File "/Users/raviailani/Documents/django-vue-admin/backend/sensory_data_app/views.py", line 204, in get_charts_data
    data = get_plain_data_within_range(
  File "/Users/raviailani/Documents/django-vue-admin/backend/sensory_data_app/views.py", line 288, in get_plain_data_within_range
    records = SensoryData.objects.filter(
  File "/Users/raviailani/Documents/envs/lib/python3.9/site-packages/django/db/models/query.py", line 840, in values
    clone = self._values(*fields, **expressions)
  File "/Users/raviailani/Documents/envs/lib/python3.9/site-packages/django/db/models/query.py", line 835, in _values
    clone.query.set_values(fields)
  File "/Users/raviailani/Documents/envs/lib/python3.9/site-packages/django/db/models/sql/query.py", line 2246, in set_values
    self.add_fields(field_names, True)
  File "/Users/raviailani/Documents/envs/lib/python3.9/site-packages/django/db/models/sql/query.py", line 1957, in add_fields
    raise FieldError("Cannot resolve keyword %r into field. "
django.core.exceptions.FieldError: Cannot resolve keyword 'entity_value' into field. Choices are: create_datetime, creator, creator_id, date_recorded, dept_belong_id, description, dissolved_oxygen, id, modifier, ph, salinity, sea_water_temperature_c, update_datetime

[2023-04-02 13:45:24,273][dvadmin.utils.exception.CustomExceptionHandler():54] [ERROR] Traceback (most recent call last):
  File "/Users/raviailani/Documents/envs/lib/python3.9/site-packages/rest_framework/views.py", line 506, in dispatch
    response = handler(request, *args, **kwargs)
  File "/Users/raviailani/Documents/envs/lib/python3.9/site-packages/rest_framework/decorators.py", line 50, in handler
    return func(*args, **kwargs)
  File "/Users/raviailani/Documents/django-vue-admin/backend/sensory_data_app/views.py", line 204, in get_charts_data
    data = get_plain_data_within_range(
  File "/Users/raviailani/Documents/django-vue-admin/backend/sensory_data_app/views.py", line 297, in get_plain_data_within_range
    res.append((data.date_recorded, data['entity_value']))
AttributeError: 'dict' object has no attribute 'date_recorded'

[2023-04-02 13:45:41,645][dvadmin.utils.exception.CustomExceptionHandler():54] [ERROR] Traceback (most recent call last):
  File "/Users/raviailani/Documents/envs/lib/python3.9/site-packages/rest_framework/views.py", line 506, in dispatch
    response = handler(request, *args, **kwargs)
  File "/Users/raviailani/Documents/envs/lib/python3.9/site-packages/rest_framework/decorators.py", line 50, in handler
    return func(*args, **kwargs)
  File "/Users/raviailani/Documents/django-vue-admin/backend/sensory_data_app/views.py", line 204, in get_charts_data
    data = get_plain_data_within_range(
  File "/Users/raviailani/Documents/django-vue-admin/backend/sensory_data_app/views.py", line 297, in get_plain_data_within_range
    res.append((data["date_recorded"], data['entity_value']))
KeyError: 'date_recorded'

[2023-04-02 13:47:44,324][dvadmin.utils.exception.CustomExceptionHandler():54] [ERROR] Traceback (most recent call last):
  File "/Users/raviailani/Documents/envs/lib/python3.9/site-packages/rest_framework/views.py", line 506, in dispatch
    response = handler(request, *args, **kwargs)
  File "/Users/raviailani/Documents/envs/lib/python3.9/site-packages/rest_framework/decorators.py", line 50, in handler
    return func(*args, **kwargs)
  File "/Users/raviailani/Documents/django-vue-admin/backend/sensory_data_app/views.py", line 204, in get_charts_data
    data = get_plain_data_within_range(
  File "/Users/raviailani/Documents/django-vue-admin/backend/sensory_data_app/views.py", line 301, in get_plain_data_within_range
    res.append((data["record_date"], data['entity_value']))
KeyError: 'record_date'

[2023-04-02 13:48:22,200][dvadmin.utils.exception.CustomExceptionHandler():54] [ERROR] Traceback (most recent call last):
  File "/Users/raviailani/Documents/envs/lib/python3.9/site-packages/rest_framework/views.py", line 506, in dispatch
    response = handler(request, *args, **kwargs)
  File "/Users/raviailani/Documents/envs/lib/python3.9/site-packages/rest_framework/decorators.py", line 50, in handler
    return func(*args, **kwargs)
  File "/Users/raviailani/Documents/django-vue-admin/backend/sensory_data_app/views.py", line 204, in get_charts_data
    data = get_plain_data_within_range(
  File "/Users/raviailani/Documents/django-vue-admin/backend/sensory_data_app/views.py", line 301, in get_plain_data_within_range
    res.append((data["record_date"], data['entity_value']))
KeyError: 'record_date'

[2023-04-02 13:50:20,508][dvadmin.utils.exception.CustomExceptionHandler():54] [ERROR] Traceback (most recent call last):
  File "/Users/raviailani/Documents/envs/lib/python3.9/site-packages/rest_framework/views.py", line 506, in dispatch
    response = handler(request, *args, **kwargs)
  File "/Users/raviailani/Documents/envs/lib/python3.9/site-packages/rest_framework/decorators.py", line 50, in handler
    return func(*args, **kwargs)
  File "/Users/raviailani/Documents/django-vue-admin/backend/sensory_data_app/views.py", line 204, in get_charts_data
    data = get_plain_data_within_range(
  File "/Users/raviailani/Documents/django-vue-admin/backend/sensory_data_app/views.py", line 298, in get_plain_data_within_range
    res.append((data["date_recorded"], data['entity_value']))
KeyError: 'date_recorded'

[2023-04-02 13:50:55,811][dvadmin.utils.exception.CustomExceptionHandler():54] [ERROR] Traceback (most recent call last):
  File "/Users/raviailani/Documents/envs/lib/python3.9/site-packages/rest_framework/views.py", line 506, in dispatch
    response = handler(request, *args, **kwargs)
  File "/Users/raviailani/Documents/envs/lib/python3.9/site-packages/rest_framework/decorators.py", line 50, in handler
    return func(*args, **kwargs)
  File "/Users/raviailani/Documents/django-vue-admin/backend/sensory_data_app/views.py", line 261, in get_charts_data
    return HttpResponse(json.dumps(res), content_type="application/json")
  File "/Users/raviailani/opt/anaconda3/lib/python3.9/json/__init__.py", line 231, in dumps
    return _default_encoder.encode(obj)
  File "/Users/raviailani/opt/anaconda3/lib/python3.9/json/encoder.py", line 199, in encode
    chunks = self.iterencode(o, _one_shot=True)
  File "/Users/raviailani/opt/anaconda3/lib/python3.9/json/encoder.py", line 257, in iterencode
    return _iterencode(o, 0)
  File "/Users/raviailani/opt/anaconda3/lib/python3.9/json/encoder.py", line 179, in default
    raise TypeError(f'Object of type {o.__class__.__name__} '
TypeError: Object of type datetime is not JSON serializable

[2023-04-02 13:54:37,452][dvadmin.utils.exception.CustomExceptionHandler():54] [ERROR] Traceback (most recent call last):
  File "/Users/raviailani/Documents/envs/lib/python3.9/site-packages/rest_framework/views.py", line 506, in dispatch
    response = handler(request, *args, **kwargs)
  File "/Users/raviailani/Documents/envs/lib/python3.9/site-packages/rest_framework/decorators.py", line 50, in handler
    return func(*args, **kwargs)
  File "/Users/raviailani/Documents/django-vue-admin/backend/sensory_data_app/views.py", line 204, in get_charts_data
    data = get_plain_data_within_range(
  File "/Users/raviailani/Documents/django-vue-admin/backend/sensory_data_app/views.py", line 299, in get_plain_data_within_range
    day = obj.date_field.strftime('%d')
AttributeError: 'datetime.datetime' object has no attribute 'date_field'

[2023-04-02 13:59:05,530][dvadmin.utils.exception.CustomExceptionHandler():54] [ERROR] Traceback (most recent call last):
  File "/Users/raviailani/Documents/envs/lib/python3.9/site-packages/rest_framework/views.py", line 506, in dispatch
    response = handler(request, *args, **kwargs)
  File "/Users/raviailani/Documents/envs/lib/python3.9/site-packages/rest_framework/decorators.py", line 50, in handler
    return func(*args, **kwargs)
  File "/Users/raviailani/Documents/django-vue-admin/backend/sensory_data_app/views.py", line 204, in get_charts_data
    data = get_plain_data_within_range(
  File "/Users/raviailani/Documents/django-vue-admin/backend/sensory_data_app/views.py", line 299, in get_plain_data_within_range
    day = obj.date_field.strftime('%d')
AttributeError: 'datetime.datetime' object has no attribute 'date_field'

[2023-04-02 14:00:56,748][dvadmin.utils.exception.CustomExceptionHandler():54] [ERROR] Traceback (most recent call last):
  File "/Users/raviailani/Documents/envs/lib/python3.9/site-packages/rest_framework/views.py", line 506, in dispatch
    response = handler(request, *args, **kwargs)
  File "/Users/raviailani/Documents/envs/lib/python3.9/site-packages/rest_framework/decorators.py", line 50, in handler
    return func(*args, **kwargs)
  File "/Users/raviailani/Documents/django-vue-admin/backend/sensory_data_app/views.py", line 204, in get_charts_data
    data = get_plain_data_within_range(
  File "/Users/raviailani/Documents/django-vue-admin/backend/sensory_data_app/views.py", line 299, in get_plain_data_within_range
    day = obj.date_field.strftime('%d')
AttributeError: 'datetime.datetime' object has no attribute 'date_field'

[2023-04-02 15:17:09,328][dvadmin.utils.exception.CustomExceptionHandler():54] [ERROR] Traceback (most recent call last):
  File "/Users/raviailani/Documents/envs/lib/python3.9/site-packages/rest_framework/views.py", line 506, in dispatch
    response = handler(request, *args, **kwargs)
  File "/Users/raviailani/Documents/django-vue-admin/backend/dvadmin/utils/import_export_mixin.py", line 301, in export_data
    assert self.export_field_label, "'%s' 请配置对应的导出模板字段。" % self.__class__.__name__
AssertionError: 'SensoryDataViewSet' 请配置对应的导出模板字段。

[2023-04-02 15:33:35,097][dvadmin.utils.exception.CustomExceptionHandler():54] [ERROR] Traceback (most recent call last):
  File "/Users/raviailani/Documents/envs/lib/python3.9/site-packages/rest_framework/views.py", line 506, in dispatch
    response = handler(request, *args, **kwargs)
  File "/Users/raviailani/Documents/django-vue-admin/backend/dvadmin/utils/import_export_mixin.py", line 303, in export_data
    data = self.export_serializer_class(queryset, many=True, request=request).data
  File "/Users/raviailani/Documents/envs/lib/python3.9/site-packages/rest_framework/serializers.py", line 745, in data
    ret = super().data
  File "/Users/raviailani/Documents/envs/lib/python3.9/site-packages/rest_framework/serializers.py", line 246, in data
    self._data = self.to_representation(self.instance)
  File "/Users/raviailani/Documents/envs/lib/python3.9/site-packages/rest_framework/serializers.py", line 663, in to_representation
    return [
  File "/Users/raviailani/Documents/envs/lib/python3.9/site-packages/rest_framework/serializers.py", line 664, in <listcomp>
    self.child.to_representation(item) for item in iterable
  File "/Users/raviailani/Documents/envs/lib/python3.9/site-packages/django_restql/mixins.py", line 149, in to_representation
    return super().to_representation(instance)
  File "/Users/raviailani/Documents/envs/lib/python3.9/site-packages/rest_framework/serializers.py", line 500, in to_representation
    for field in fields:
  File "/Users/raviailani/Documents/envs/lib/python3.9/site-packages/rest_framework/serializers.py", line 361, in _readable_fields
    for field in self.fields.values():
  File "/Users/raviailani/Documents/envs/lib/python3.9/site-packages/django_restql/mixins.py", line 423, in fields
    return self.dynamic_fields
  File "/Users/raviailani/Documents/envs/lib/python3.9/site-packages/django/utils/functional.py", line 48, in __get__
    res = instance.__dict__[self.name] = self.func(instance)
  File "/Users/raviailani/Documents/envs/lib/python3.9/site-packages/django_restql/mixins.py", line 383, in dynamic_fields
    return self.allowed_fields
  File "/Users/raviailani/Documents/envs/lib/python3.9/site-packages/django/utils/functional.py", line 48, in __get__
    res = instance.__dict__[self.name] = self.func(instance)
  File "/Users/raviailani/Documents/envs/lib/python3.9/site-packages/django_restql/mixins.py", line 153, in allowed_fields
    fields = super().fields
  File "/Users/raviailani/Documents/envs/lib/python3.9/site-packages/django/utils/functional.py", line 48, in __get__
    res = instance.__dict__[self.name] = self.func(instance)
  File "/Users/raviailani/Documents/envs/lib/python3.9/site-packages/rest_framework/serializers.py", line 350, in fields
    fields[key] = value
  File "/Users/raviailani/Documents/envs/lib/python3.9/site-packages/rest_framework/utils/serializer_helpers.py", line 152, in __setitem__
    field.bind(field_name=key, parent=self.serializer)
  File "/Users/raviailani/Documents/envs/lib/python3.9/site-packages/rest_framework/fields.py", line 378, in bind
    assert self.source != field_name, (
AssertionError: It is redundant to specify `source='sea_water_temperature_c'` on field 'FloatField' in serializer 'ExportSensoryDataSerializer', because it is the same as the field name. Remove the `source` keyword argument.

[2023-04-02 15:36:20,246][dvadmin.utils.exception.CustomExceptionHandler():54] [ERROR] Traceback (most recent call last):
  File "/Users/raviailani/Documents/envs/lib/python3.9/site-packages/rest_framework/views.py", line 506, in dispatch
    response = handler(request, *args, **kwargs)
  File "/Users/raviailani/Documents/django-vue-admin/backend/dvadmin/utils/viewset.py", line 80, in list
    page = self.paginate_queryset(queryset)
  File "/Users/raviailani/Documents/envs/lib/python3.9/site-packages/rest_framework/generics.py", line 171, in paginate_queryset
    return self.paginator.paginate_queryset(queryset, self.request, view=self)
  File "/Users/raviailani/Documents/envs/lib/python3.9/site-packages/rest_framework/pagination.py", line 204, in paginate_queryset
    self.page = paginator.page(page_number)
  File "/Users/raviailani/Documents/envs/lib/python3.9/site-packages/django/core/paginator.py", line 76, in page
    number = self.validate_number(number)
  File "/Users/raviailani/Documents/envs/lib/python3.9/site-packages/django/core/paginator.py", line 54, in validate_number
    if number > self.num_pages:
  File "/Users/raviailani/Documents/envs/lib/python3.9/site-packages/django/utils/functional.py", line 48, in __get__
    res = instance.__dict__[self.name] = self.func(instance)
  File "/Users/raviailani/Documents/envs/lib/python3.9/site-packages/django/core/paginator.py", line 103, in num_pages
    if self.count == 0 and not self.allow_empty_first_page:
  File "/Users/raviailani/Documents/envs/lib/python3.9/site-packages/django/utils/functional.py", line 48, in __get__
    res = instance.__dict__[self.name] = self.func(instance)
  File "/Users/raviailani/Documents/envs/lib/python3.9/site-packages/django/core/paginator.py", line 97, in count
    return c()
  File "/Users/raviailani/Documents/envs/lib/python3.9/site-packages/django/db/models/query.py", line 412, in count
    return self.query.get_count(using=self.db)
  File "/Users/raviailani/Documents/envs/lib/python3.9/site-packages/django/db/models/sql/query.py", line 517, in get_count
    number = obj.get_aggregation(using, ['__count'])['__count']
  File "/Users/raviailani/Documents/envs/lib/python3.9/site-packages/django/db/models/sql/query.py", line 502, in get_aggregation
    result = compiler.execute_sql(SINGLE)
  File "/Users/raviailani/Documents/envs/lib/python3.9/site-packages/django/db/models/sql/compiler.py", line 1162, in execute_sql
    sql, params = self.as_sql()
  File "/Users/raviailani/Documents/envs/lib/python3.9/site-packages/django/db/models/sql/compiler.py", line 528, in as_sql
    where, w_params = self.compile(self.where) if self.where is not None else ("", [])
  File "/Users/raviailani/Documents/envs/lib/python3.9/site-packages/django/db/models/sql/compiler.py", line 445, in compile
    sql, params = node.as_sql(self, self.connection)
  File "/Users/raviailani/Documents/envs/lib/python3.9/site-packages/django/db/models/sql/where.py", line 81, in as_sql
    sql, params = compiler.compile(child)
  File "/Users/raviailani/Documents/envs/lib/python3.9/site-packages/django/db/models/sql/compiler.py", line 445, in compile
    sql, params = node.as_sql(self, self.connection)
  File "/Users/raviailani/Documents/envs/lib/python3.9/site-packages/django/db/models/lookups.py", line 315, in as_sql
    return super().as_sql(compiler, connection)
  File "/Users/raviailani/Documents/envs/lib/python3.9/site-packages/django/db/models/lookups.py", line 194, in as_sql
    rhs_sql, rhs_params = self.process_rhs(compiler, connection)
  File "/Users/raviailani/Documents/envs/lib/python3.9/site-packages/django/db/models/lookups.py", line 301, in process_rhs
    return super().process_rhs(compiler, connection)
  File "/Users/raviailani/Documents/envs/lib/python3.9/site-packages/django/db/models/lookups.py", line 101, in process_rhs
    return self.get_db_prep_lookup(value, connection)
  File "/Users/raviailani/Documents/envs/lib/python3.9/site-packages/django/db/models/lookups.py", line 219, in get_db_prep_lookup
    [get_db_prep_value(value, connection, prepared=True)]
  File "/Users/raviailani/Documents/envs/lib/python3.9/site-packages/django/db/models/fields/__init__.py", line 1428, in get_db_prep_value
    return connection.ops.adapt_datetimefield_value(value)
  File "/Users/raviailani/Documents/envs/lib/python3.9/site-packages/django/db/backends/mysql/operations.py", line 250, in adapt_datetimefield_value
    raise ValueError("MySQL backend does not support timezone-aware datetimes when USE_TZ is False.")
ValueError: MySQL backend does not support timezone-aware datetimes when USE_TZ is False.

[2023-04-02 15:37:13,074][dvadmin.utils.exception.CustomExceptionHandler():54] [ERROR] Traceback (most recent call last):
  File "/Users/raviailani/Documents/envs/lib/python3.9/site-packages/rest_framework/views.py", line 506, in dispatch
    response = handler(request, *args, **kwargs)
  File "/Users/raviailani/Documents/django-vue-admin/backend/dvadmin/utils/viewset.py", line 79, in list
    queryset = self.filter_queryset(self.get_queryset())
  File "/Users/raviailani/Documents/django-vue-admin/backend/dvadmin/utils/viewset.py", line 46, in filter_queryset
    queryset = backend().filter_queryset(self.request, queryset, self)
  File "/Users/raviailani/Documents/django-vue-admin/backend/dvadmin/utils/filters.py", line 305, in filter_queryset
    queryset = queryset.filter(reduce(operator.and_, conditions))
  File "/Users/raviailani/Documents/envs/lib/python3.9/site-packages/django/db/models/query.py", line 941, in filter
    return self._filter_or_exclude(False, args, kwargs)
  File "/Users/raviailani/Documents/envs/lib/python3.9/site-packages/django/db/models/query.py", line 961, in _filter_or_exclude
    clone._filter_or_exclude_inplace(negate, args, kwargs)
  File "/Users/raviailani/Documents/envs/lib/python3.9/site-packages/django/db/models/query.py", line 968, in _filter_or_exclude_inplace
    self._query.add_q(Q(*args, **kwargs))
  File "/Users/raviailani/Documents/envs/lib/python3.9/site-packages/django/db/models/sql/query.py", line 1391, in add_q
    clause, _ = self._add_q(q_object, self.used_aliases)
  File "/Users/raviailani/Documents/envs/lib/python3.9/site-packages/django/db/models/sql/query.py", line 1410, in _add_q
    child_clause, needed_inner = self.build_filter(
  File "/Users/raviailani/Documents/envs/lib/python3.9/site-packages/django/db/models/sql/query.py", line 1263, in build_filter
    return self._add_q(
  File "/Users/raviailani/Documents/envs/lib/python3.9/site-packages/django/db/models/sql/query.py", line 1410, in _add_q
    child_clause, needed_inner = self.build_filter(
  File "/Users/raviailani/Documents/envs/lib/python3.9/site-packages/django/db/models/sql/query.py", line 1345, in build_filter
    condition = self.build_lookup(lookups, col, value)
  File "/Users/raviailani/Documents/envs/lib/python3.9/site-packages/django/db/models/sql/query.py", line 1191, in build_lookup
    lookup = lookup_class(lhs, rhs)
  File "/Users/raviailani/Documents/envs/lib/python3.9/site-packages/django/db/models/lookups.py", line 25, in __init__
    self.rhs = self.get_prep_lookup()
  File "/Users/raviailani/Documents/envs/lib/python3.9/site-packages/django/db/models/lookups.py", line 77, in get_prep_lookup
    return self.lhs.output_field.get_prep_value(self.rhs)
  File "/Users/raviailani/Documents/envs/lib/python3.9/site-packages/django/db/models/fields/__init__.py", line 1406, in get_prep_value
    value = super().get_prep_value(value)
  File "/Users/raviailani/Documents/envs/lib/python3.9/site-packages/django/db/models/fields/__init__.py", line 1266, in get_prep_value
    return self.to_python(value)
  File "/Users/raviailani/Documents/envs/lib/python3.9/site-packages/django/db/models/fields/__init__.py", line 1388, in to_python
    raise exceptions.ValidationError(
django.core.exceptions.ValidationError: ['“”的值有一个错误的日期格式。它的格式应该是YYYY-MM-DD HH:MM[:ss[.uuuuuu]][TZ] ']

[2023-04-02 15:37:37,548][dvadmin.utils.exception.CustomExceptionHandler():54] [ERROR] Traceback (most recent call last):
  File "/Users/raviailani/Documents/envs/lib/python3.9/site-packages/rest_framework/views.py", line 506, in dispatch
    response = handler(request, *args, **kwargs)
  File "/Users/raviailani/Documents/django-vue-admin/backend/dvadmin/utils/import_export_mixin.py", line 300, in export_data
    queryset = self.filter_queryset(self.get_queryset())
  File "/Users/raviailani/Documents/django-vue-admin/backend/dvadmin/utils/viewset.py", line 46, in filter_queryset
    queryset = backend().filter_queryset(self.request, queryset, self)
  File "/Users/raviailani/Documents/django-vue-admin/backend/dvadmin/utils/filters.py", line 305, in filter_queryset
    queryset = queryset.filter(reduce(operator.and_, conditions))
  File "/Users/raviailani/Documents/envs/lib/python3.9/site-packages/django/db/models/query.py", line 941, in filter
    return self._filter_or_exclude(False, args, kwargs)
  File "/Users/raviailani/Documents/envs/lib/python3.9/site-packages/django/db/models/query.py", line 961, in _filter_or_exclude
    clone._filter_or_exclude_inplace(negate, args, kwargs)
  File "/Users/raviailani/Documents/envs/lib/python3.9/site-packages/django/db/models/query.py", line 968, in _filter_or_exclude_inplace
    self._query.add_q(Q(*args, **kwargs))
  File "/Users/raviailani/Documents/envs/lib/python3.9/site-packages/django/db/models/sql/query.py", line 1391, in add_q
    clause, _ = self._add_q(q_object, self.used_aliases)
  File "/Users/raviailani/Documents/envs/lib/python3.9/site-packages/django/db/models/sql/query.py", line 1410, in _add_q
    child_clause, needed_inner = self.build_filter(
  File "/Users/raviailani/Documents/envs/lib/python3.9/site-packages/django/db/models/sql/query.py", line 1263, in build_filter
    return self._add_q(
  File "/Users/raviailani/Documents/envs/lib/python3.9/site-packages/django/db/models/sql/query.py", line 1410, in _add_q
    child_clause, needed_inner = self.build_filter(
  File "/Users/raviailani/Documents/envs/lib/python3.9/site-packages/django/db/models/sql/query.py", line 1345, in build_filter
    condition = self.build_lookup(lookups, col, value)
  File "/Users/raviailani/Documents/envs/lib/python3.9/site-packages/django/db/models/sql/query.py", line 1191, in build_lookup
    lookup = lookup_class(lhs, rhs)
  File "/Users/raviailani/Documents/envs/lib/python3.9/site-packages/django/db/models/lookups.py", line 25, in __init__
    self.rhs = self.get_prep_lookup()
  File "/Users/raviailani/Documents/envs/lib/python3.9/site-packages/django/db/models/lookups.py", line 77, in get_prep_lookup
    return self.lhs.output_field.get_prep_value(self.rhs)
  File "/Users/raviailani/Documents/envs/lib/python3.9/site-packages/django/db/models/fields/__init__.py", line 1406, in get_prep_value
    value = super().get_prep_value(value)
  File "/Users/raviailani/Documents/envs/lib/python3.9/site-packages/django/db/models/fields/__init__.py", line 1266, in get_prep_value
    return self.to_python(value)
  File "/Users/raviailani/Documents/envs/lib/python3.9/site-packages/django/db/models/fields/__init__.py", line 1388, in to_python
    raise exceptions.ValidationError(
django.core.exceptions.ValidationError: ['“”的值有一个错误的日期格式。它的格式应该是YYYY-MM-DD HH:MM[:ss[.uuuuuu]][TZ] ']

[2023-04-02 15:38:17,600][dvadmin.utils.exception.CustomExceptionHandler():54] [ERROR] Traceback (most recent call last):
  File "/Users/raviailani/Documents/envs/lib/python3.9/site-packages/rest_framework/views.py", line 506, in dispatch
    response = handler(request, *args, **kwargs)
  File "/Users/raviailani/Documents/django-vue-admin/backend/dvadmin/utils/import_export_mixin.py", line 300, in export_data
    queryset = self.filter_queryset(self.get_queryset())
  File "/Users/raviailani/Documents/django-vue-admin/backend/dvadmin/utils/viewset.py", line 46, in filter_queryset
    queryset = backend().filter_queryset(self.request, queryset, self)
  File "/Users/raviailani/Documents/django-vue-admin/backend/dvadmin/utils/filters.py", line 305, in filter_queryset
    queryset = queryset.filter(reduce(operator.and_, conditions))
  File "/Users/raviailani/Documents/envs/lib/python3.9/site-packages/django/db/models/query.py", line 941, in filter
    return self._filter_or_exclude(False, args, kwargs)
  File "/Users/raviailani/Documents/envs/lib/python3.9/site-packages/django/db/models/query.py", line 961, in _filter_or_exclude
    clone._filter_or_exclude_inplace(negate, args, kwargs)
  File "/Users/raviailani/Documents/envs/lib/python3.9/site-packages/django/db/models/query.py", line 968, in _filter_or_exclude_inplace
    self._query.add_q(Q(*args, **kwargs))
  File "/Users/raviailani/Documents/envs/lib/python3.9/site-packages/django/db/models/sql/query.py", line 1391, in add_q
    clause, _ = self._add_q(q_object, self.used_aliases)
  File "/Users/raviailani/Documents/envs/lib/python3.9/site-packages/django/db/models/sql/query.py", line 1410, in _add_q
    child_clause, needed_inner = self.build_filter(
  File "/Users/raviailani/Documents/envs/lib/python3.9/site-packages/django/db/models/sql/query.py", line 1263, in build_filter
    return self._add_q(
  File "/Users/raviailani/Documents/envs/lib/python3.9/site-packages/django/db/models/sql/query.py", line 1410, in _add_q
    child_clause, needed_inner = self.build_filter(
  File "/Users/raviailani/Documents/envs/lib/python3.9/site-packages/django/db/models/sql/query.py", line 1345, in build_filter
    condition = self.build_lookup(lookups, col, value)
  File "/Users/raviailani/Documents/envs/lib/python3.9/site-packages/django/db/models/sql/query.py", line 1191, in build_lookup
    lookup = lookup_class(lhs, rhs)
  File "/Users/raviailani/Documents/envs/lib/python3.9/site-packages/django/db/models/lookups.py", line 25, in __init__
    self.rhs = self.get_prep_lookup()
  File "/Users/raviailani/Documents/envs/lib/python3.9/site-packages/django/db/models/lookups.py", line 77, in get_prep_lookup
    return self.lhs.output_field.get_prep_value(self.rhs)
  File "/Users/raviailani/Documents/envs/lib/python3.9/site-packages/django/db/models/fields/__init__.py", line 1406, in get_prep_value
    value = super().get_prep_value(value)
  File "/Users/raviailani/Documents/envs/lib/python3.9/site-packages/django/db/models/fields/__init__.py", line 1266, in get_prep_value
    return self.to_python(value)
  File "/Users/raviailani/Documents/envs/lib/python3.9/site-packages/django/db/models/fields/__init__.py", line 1388, in to_python
    raise exceptions.ValidationError(
django.core.exceptions.ValidationError: ['“”的值有一个错误的日期格式。它的格式应该是YYYY-MM-DD HH:MM[:ss[.uuuuuu]][TZ] ']

[2023-04-02 15:41:33,241][dvadmin.utils.exception.CustomExceptionHandler():54] [ERROR] Traceback (most recent call last):
  File "/Users/raviailani/Documents/envs/lib/python3.9/site-packages/rest_framework/views.py", line 506, in dispatch
    response = handler(request, *args, **kwargs)
  File "/Users/raviailani/Documents/django-vue-admin/backend/dvadmin/utils/viewset.py", line 80, in list
    page = self.paginate_queryset(queryset)
  File "/Users/raviailani/Documents/envs/lib/python3.9/site-packages/rest_framework/generics.py", line 171, in paginate_queryset
    return self.paginator.paginate_queryset(queryset, self.request, view=self)
  File "/Users/raviailani/Documents/envs/lib/python3.9/site-packages/rest_framework/pagination.py", line 204, in paginate_queryset
    self.page = paginator.page(page_number)
  File "/Users/raviailani/Documents/envs/lib/python3.9/site-packages/django/core/paginator.py", line 76, in page
    number = self.validate_number(number)
  File "/Users/raviailani/Documents/envs/lib/python3.9/site-packages/django/core/paginator.py", line 54, in validate_number
    if number > self.num_pages:
  File "/Users/raviailani/Documents/envs/lib/python3.9/site-packages/django/utils/functional.py", line 48, in __get__
    res = instance.__dict__[self.name] = self.func(instance)
  File "/Users/raviailani/Documents/envs/lib/python3.9/site-packages/django/core/paginator.py", line 103, in num_pages
    if self.count == 0 and not self.allow_empty_first_page:
  File "/Users/raviailani/Documents/envs/lib/python3.9/site-packages/django/utils/functional.py", line 48, in __get__
    res = instance.__dict__[self.name] = self.func(instance)
  File "/Users/raviailani/Documents/envs/lib/python3.9/site-packages/django/core/paginator.py", line 97, in count
    return c()
  File "/Users/raviailani/Documents/envs/lib/python3.9/site-packages/django/db/models/query.py", line 412, in count
    return self.query.get_count(using=self.db)
  File "/Users/raviailani/Documents/envs/lib/python3.9/site-packages/django/db/models/sql/query.py", line 517, in get_count
    number = obj.get_aggregation(using, ['__count'])['__count']
  File "/Users/raviailani/Documents/envs/lib/python3.9/site-packages/django/db/models/sql/query.py", line 502, in get_aggregation
    result = compiler.execute_sql(SINGLE)
  File "/Users/raviailani/Documents/envs/lib/python3.9/site-packages/django/db/models/sql/compiler.py", line 1162, in execute_sql
    sql, params = self.as_sql()
  File "/Users/raviailani/Documents/envs/lib/python3.9/site-packages/django/db/models/sql/compiler.py", line 528, in as_sql
    where, w_params = self.compile(self.where) if self.where is not None else ("", [])
  File "/Users/raviailani/Documents/envs/lib/python3.9/site-packages/django/db/models/sql/compiler.py", line 445, in compile
    sql, params = node.as_sql(self, self.connection)
  File "/Users/raviailani/Documents/envs/lib/python3.9/site-packages/django/db/models/sql/where.py", line 81, in as_sql
    sql, params = compiler.compile(child)
  File "/Users/raviailani/Documents/envs/lib/python3.9/site-packages/django/db/models/sql/compiler.py", line 445, in compile
    sql, params = node.as_sql(self, self.connection)
  File "/Users/raviailani/Documents/envs/lib/python3.9/site-packages/django/db/models/lookups.py", line 315, in as_sql
    return super().as_sql(compiler, connection)
  File "/Users/raviailani/Documents/envs/lib/python3.9/site-packages/django/db/models/lookups.py", line 194, in as_sql
    rhs_sql, rhs_params = self.process_rhs(compiler, connection)
  File "/Users/raviailani/Documents/envs/lib/python3.9/site-packages/django/db/models/lookups.py", line 301, in process_rhs
    return super().process_rhs(compiler, connection)
  File "/Users/raviailani/Documents/envs/lib/python3.9/site-packages/django/db/models/lookups.py", line 101, in process_rhs
    return self.get_db_prep_lookup(value, connection)
  File "/Users/raviailani/Documents/envs/lib/python3.9/site-packages/django/db/models/lookups.py", line 219, in get_db_prep_lookup
    [get_db_prep_value(value, connection, prepared=True)]
  File "/Users/raviailani/Documents/envs/lib/python3.9/site-packages/django/db/models/fields/__init__.py", line 1428, in get_db_prep_value
    return connection.ops.adapt_datetimefield_value(value)
  File "/Users/raviailani/Documents/envs/lib/python3.9/site-packages/django/db/backends/mysql/operations.py", line 250, in adapt_datetimefield_value
    raise ValueError("MySQL backend does not support timezone-aware datetimes when USE_TZ is False.")
ValueError: MySQL backend does not support timezone-aware datetimes when USE_TZ is False.

[2023-04-02 15:42:24,023][dvadmin.utils.exception.CustomExceptionHandler():54] [ERROR] Traceback (most recent call last):
  File "/Users/raviailani/Documents/envs/lib/python3.9/site-packages/rest_framework/views.py", line 506, in dispatch
    response = handler(request, *args, **kwargs)
  File "/Users/raviailani/Documents/django-vue-admin/backend/dvadmin/utils/viewset.py", line 80, in list
    page = self.paginate_queryset(queryset)
  File "/Users/raviailani/Documents/envs/lib/python3.9/site-packages/rest_framework/generics.py", line 171, in paginate_queryset
    return self.paginator.paginate_queryset(queryset, self.request, view=self)
  File "/Users/raviailani/Documents/envs/lib/python3.9/site-packages/rest_framework/pagination.py", line 204, in paginate_queryset
    self.page = paginator.page(page_number)
  File "/Users/raviailani/Documents/envs/lib/python3.9/site-packages/django/core/paginator.py", line 76, in page
    number = self.validate_number(number)
  File "/Users/raviailani/Documents/envs/lib/python3.9/site-packages/django/core/paginator.py", line 54, in validate_number
    if number > self.num_pages:
  File "/Users/raviailani/Documents/envs/lib/python3.9/site-packages/django/utils/functional.py", line 48, in __get__
    res = instance.__dict__[self.name] = self.func(instance)
  File "/Users/raviailani/Documents/envs/lib/python3.9/site-packages/django/core/paginator.py", line 103, in num_pages
    if self.count == 0 and not self.allow_empty_first_page:
  File "/Users/raviailani/Documents/envs/lib/python3.9/site-packages/django/utils/functional.py", line 48, in __get__
    res = instance.__dict__[self.name] = self.func(instance)
  File "/Users/raviailani/Documents/envs/lib/python3.9/site-packages/django/core/paginator.py", line 97, in count
    return c()
  File "/Users/raviailani/Documents/envs/lib/python3.9/site-packages/django/db/models/query.py", line 412, in count
    return self.query.get_count(using=self.db)
  File "/Users/raviailani/Documents/envs/lib/python3.9/site-packages/django/db/models/sql/query.py", line 517, in get_count
    number = obj.get_aggregation(using, ['__count'])['__count']
  File "/Users/raviailani/Documents/envs/lib/python3.9/site-packages/django/db/models/sql/query.py", line 502, in get_aggregation
    result = compiler.execute_sql(SINGLE)
  File "/Users/raviailani/Documents/envs/lib/python3.9/site-packages/django/db/models/sql/compiler.py", line 1162, in execute_sql
    sql, params = self.as_sql()
  File "/Users/raviailani/Documents/envs/lib/python3.9/site-packages/django/db/models/sql/compiler.py", line 528, in as_sql
    where, w_params = self.compile(self.where) if self.where is not None else ("", [])
  File "/Users/raviailani/Documents/envs/lib/python3.9/site-packages/django/db/models/sql/compiler.py", line 445, in compile
    sql, params = node.as_sql(self, self.connection)
  File "/Users/raviailani/Documents/envs/lib/python3.9/site-packages/django/db/models/sql/where.py", line 81, in as_sql
    sql, params = compiler.compile(child)
  File "/Users/raviailani/Documents/envs/lib/python3.9/site-packages/django/db/models/sql/compiler.py", line 445, in compile
    sql, params = node.as_sql(self, self.connection)
  File "/Users/raviailani/Documents/envs/lib/python3.9/site-packages/django/db/models/lookups.py", line 315, in as_sql
    return super().as_sql(compiler, connection)
  File "/Users/raviailani/Documents/envs/lib/python3.9/site-packages/django/db/models/lookups.py", line 194, in as_sql
    rhs_sql, rhs_params = self.process_rhs(compiler, connection)
  File "/Users/raviailani/Documents/envs/lib/python3.9/site-packages/django/db/models/lookups.py", line 301, in process_rhs
    return super().process_rhs(compiler, connection)
  File "/Users/raviailani/Documents/envs/lib/python3.9/site-packages/django/db/models/lookups.py", line 101, in process_rhs
    return self.get_db_prep_lookup(value, connection)
  File "/Users/raviailani/Documents/envs/lib/python3.9/site-packages/django/db/models/lookups.py", line 219, in get_db_prep_lookup
    [get_db_prep_value(value, connection, prepared=True)]
  File "/Users/raviailani/Documents/envs/lib/python3.9/site-packages/django/db/models/fields/__init__.py", line 1428, in get_db_prep_value
    return connection.ops.adapt_datetimefield_value(value)
  File "/Users/raviailani/Documents/envs/lib/python3.9/site-packages/django/db/backends/mysql/operations.py", line 250, in adapt_datetimefield_value
    raise ValueError("MySQL backend does not support timezone-aware datetimes when USE_TZ is False.")
ValueError: MySQL backend does not support timezone-aware datetimes when USE_TZ is False.

[2023-04-02 16:06:27,963][dvadmin.utils.exception.CustomExceptionHandler():54] [ERROR] Traceback (most recent call last):
  File "/Users/raviailani/Documents/envs/lib/python3.9/site-packages/rest_framework/views.py", line 506, in dispatch
    response = handler(request, *args, **kwargs)
  File "/Users/raviailani/Documents/django-vue-admin/backend/dvadmin/utils/viewset.py", line 79, in list
    queryset = self.filter_queryset(self.get_queryset())
  File "/Users/raviailani/Documents/django-vue-admin/backend/dvadmin/utils/viewset.py", line 46, in filter_queryset
    queryset = backend().filter_queryset(self.request, queryset, self)
  File "/Users/raviailani/Documents/django-vue-admin/backend/dvadmin/utils/filters.py", line 305, in filter_queryset
    queryset = queryset.filter(reduce(operator.and_, conditions))
  File "/Users/raviailani/Documents/envs/lib/python3.9/site-packages/django/db/models/query.py", line 941, in filter
    return self._filter_or_exclude(False, args, kwargs)
  File "/Users/raviailani/Documents/envs/lib/python3.9/site-packages/django/db/models/query.py", line 961, in _filter_or_exclude
    clone._filter_or_exclude_inplace(negate, args, kwargs)
  File "/Users/raviailani/Documents/envs/lib/python3.9/site-packages/django/db/models/query.py", line 968, in _filter_or_exclude_inplace
    self._query.add_q(Q(*args, **kwargs))
  File "/Users/raviailani/Documents/envs/lib/python3.9/site-packages/django/db/models/sql/query.py", line 1391, in add_q
    clause, _ = self._add_q(q_object, self.used_aliases)
  File "/Users/raviailani/Documents/envs/lib/python3.9/site-packages/django/db/models/sql/query.py", line 1410, in _add_q
    child_clause, needed_inner = self.build_filter(
  File "/Users/raviailani/Documents/envs/lib/python3.9/site-packages/django/db/models/sql/query.py", line 1263, in build_filter
    return self._add_q(
  File "/Users/raviailani/Documents/envs/lib/python3.9/site-packages/django/db/models/sql/query.py", line 1410, in _add_q
    child_clause, needed_inner = self.build_filter(
  File "/Users/raviailani/Documents/envs/lib/python3.9/site-packages/django/db/models/sql/query.py", line 1345, in build_filter
    condition = self.build_lookup(lookups, col, value)
  File "/Users/raviailani/Documents/envs/lib/python3.9/site-packages/django/db/models/sql/query.py", line 1191, in build_lookup
    lookup = lookup_class(lhs, rhs)
  File "/Users/raviailani/Documents/envs/lib/python3.9/site-packages/django/db/models/lookups.py", line 25, in __init__
    self.rhs = self.get_prep_lookup()
  File "/Users/raviailani/Documents/envs/lib/python3.9/site-packages/django/db/models/lookups.py", line 77, in get_prep_lookup
    return self.lhs.output_field.get_prep_value(self.rhs)
  File "/Users/raviailani/Documents/envs/lib/python3.9/site-packages/django/db/models/fields/__init__.py", line 1406, in get_prep_value
    value = super().get_prep_value(value)
  File "/Users/raviailani/Documents/envs/lib/python3.9/site-packages/django/db/models/fields/__init__.py", line 1266, in get_prep_value
    return self.to_python(value)
  File "/Users/raviailani/Documents/envs/lib/python3.9/site-packages/django/db/models/fields/__init__.py", line 1388, in to_python
    raise exceptions.ValidationError(
django.core.exceptions.ValidationError: ['“07/13/2022”的值有一个错误的日期格式。它的格式应该是YYYY-MM-DD HH:MM[:ss[.uuuuuu]][TZ] ']

[2023-04-02 16:38:11,717][dvadmin.utils.exception.CustomExceptionHandler():54] [ERROR] Traceback (most recent call last):
  File "/Users/raviailani/Documents/envs/lib/python3.9/site-packages/rest_framework/views.py", line 506, in dispatch
    response = handler(request, *args, **kwargs)
  File "/Users/raviailani/Documents/envs/lib/python3.9/site-packages/rest_framework/decorators.py", line 50, in handler
    return func(*args, **kwargs)
  File "/Users/raviailani/Documents/django-vue-admin/backend/sensory_data_app/views.py", line 398, in get_data_within_range
    data = data_queryset[start_index:end_index].values()
AttributeError: 'list' object has no attribute 'values'

[2023-04-02 16:38:52,138][dvadmin.utils.exception.CustomExceptionHandler():54] [ERROR] Traceback (most recent call last):
  File "/Users/raviailani/Documents/envs/lib/python3.9/site-packages/rest_framework/views.py", line 506, in dispatch
    response = handler(request, *args, **kwargs)
  File "/Users/raviailani/Documents/envs/lib/python3.9/site-packages/rest_framework/decorators.py", line 50, in handler
    return func(*args, **kwargs)
  File "/Users/raviailani/Documents/django-vue-admin/backend/sensory_data_app/views.py", line 399, in get_data_within_range
    data = data_queryset[start_index:end_index].values()
AttributeError: 'list' object has no attribute 'values'

[2023-04-02 16:41:36,713][dvadmin.utils.exception.CustomExceptionHandler():54] [ERROR] Traceback (most recent call last):
  File "/Users/raviailani/Documents/envs/lib/python3.9/site-packages/rest_framework/views.py", line 506, in dispatch
    response = handler(request, *args, **kwargs)
  File "/Users/raviailani/Documents/django-vue-admin/backend/dvadmin/utils/viewset.py", line 79, in list
    queryset = self.filter_queryset(self.get_queryset())
  File "/Users/raviailani/Documents/django-vue-admin/backend/dvadmin/utils/viewset.py", line 46, in filter_queryset
    queryset = backend().filter_queryset(self.request, queryset, self)
  File "/Users/raviailani/Documents/django-vue-admin/backend/dvadmin/utils/filters.py", line 305, in filter_queryset
    queryset = queryset.filter(reduce(operator.and_, conditions))
  File "/Users/raviailani/Documents/envs/lib/python3.9/site-packages/django/db/models/query.py", line 941, in filter
    return self._filter_or_exclude(False, args, kwargs)
  File "/Users/raviailani/Documents/envs/lib/python3.9/site-packages/django/db/models/query.py", line 961, in _filter_or_exclude
    clone._filter_or_exclude_inplace(negate, args, kwargs)
  File "/Users/raviailani/Documents/envs/lib/python3.9/site-packages/django/db/models/query.py", line 968, in _filter_or_exclude_inplace
    self._query.add_q(Q(*args, **kwargs))
  File "/Users/raviailani/Documents/envs/lib/python3.9/site-packages/django/db/models/sql/query.py", line 1391, in add_q
    clause, _ = self._add_q(q_object, self.used_aliases)
  File "/Users/raviailani/Documents/envs/lib/python3.9/site-packages/django/db/models/sql/query.py", line 1410, in _add_q
    child_clause, needed_inner = self.build_filter(
  File "/Users/raviailani/Documents/envs/lib/python3.9/site-packages/django/db/models/sql/query.py", line 1263, in build_filter
    return self._add_q(
  File "/Users/raviailani/Documents/envs/lib/python3.9/site-packages/django/db/models/sql/query.py", line 1410, in _add_q
    child_clause, needed_inner = self.build_filter(
  File "/Users/raviailani/Documents/envs/lib/python3.9/site-packages/django/db/models/sql/query.py", line 1345, in build_filter
    condition = self.build_lookup(lookups, col, value)
  File "/Users/raviailani/Documents/envs/lib/python3.9/site-packages/django/db/models/sql/query.py", line 1191, in build_lookup
    lookup = lookup_class(lhs, rhs)
  File "/Users/raviailani/Documents/envs/lib/python3.9/site-packages/django/db/models/lookups.py", line 25, in __init__
    self.rhs = self.get_prep_lookup()
  File "/Users/raviailani/Documents/envs/lib/python3.9/site-packages/django/db/models/lookups.py", line 77, in get_prep_lookup
    return self.lhs.output_field.get_prep_value(self.rhs)
  File "/Users/raviailani/Documents/envs/lib/python3.9/site-packages/django/db/models/fields/__init__.py", line 1406, in get_prep_value
    value = super().get_prep_value(value)
  File "/Users/raviailani/Documents/envs/lib/python3.9/site-packages/django/db/models/fields/__init__.py", line 1266, in get_prep_value
    return self.to_python(value)
  File "/Users/raviailani/Documents/envs/lib/python3.9/site-packages/django/db/models/fields/__init__.py", line 1388, in to_python
    raise exceptions.ValidationError(
django.core.exceptions.ValidationError: ['“”的值有一个错误的日期格式。它的格式应该是YYYY-MM-DD HH:MM[:ss[.uuuuuu]][TZ] ']

[2023-04-02 16:44:34,336][dvadmin.utils.exception.CustomExceptionHandler():54] [ERROR] Traceback (most recent call last):
  File "/Users/raviailani/Documents/envs/lib/python3.9/site-packages/rest_framework/views.py", line 506, in dispatch
    response = handler(request, *args, **kwargs)
  File "/Users/raviailani/Documents/envs/lib/python3.9/site-packages/rest_framework/decorators.py", line 50, in handler
    return func(*args, **kwargs)
  File "/Users/raviailani/Documents/django-vue-admin/backend/sensory_data_app/views.py", line 413, in get_data_within_range
    return HttpResponse(json.dumps(response), content_type="application/json")
  File "/Users/raviailani/opt/anaconda3/lib/python3.9/json/__init__.py", line 231, in dumps
    return _default_encoder.encode(obj)
  File "/Users/raviailani/opt/anaconda3/lib/python3.9/json/encoder.py", line 199, in encode
    chunks = self.iterencode(o, _one_shot=True)
  File "/Users/raviailani/opt/anaconda3/lib/python3.9/json/encoder.py", line 257, in iterencode
    return _iterencode(o, 0)
  File "/Users/raviailani/opt/anaconda3/lib/python3.9/json/encoder.py", line 179, in default
    raise TypeError(f'Object of type {o.__class__.__name__} '
TypeError: Object of type SensoryData is not JSON serializable

[2023-04-02 16:46:11,786][dvadmin.utils.exception.CustomExceptionHandler():54] [ERROR] Traceback (most recent call last):
  File "/Users/raviailani/Documents/envs/lib/python3.9/site-packages/rest_framework/views.py", line 506, in dispatch
    response = handler(request, *args, **kwargs)
  File "/Users/raviailani/Documents/envs/lib/python3.9/site-packages/rest_framework/decorators.py", line 50, in handler
    return func(*args, **kwargs)
  File "/Users/raviailani/Documents/django-vue-admin/backend/sensory_data_app/views.py", line 386, in get_data_within_range
    data_queryset = SensoryData.objects.filter(
  File "/Users/raviailani/Documents/envs/lib/python3.9/site-packages/django/db/models/manager.py", line 85, in manager_method
    return getattr(self.get_queryset(), name)(*args, **kwargs)
  File "/Users/raviailani/Documents/envs/lib/python3.9/site-packages/django/db/models/query.py", line 941, in filter
    return self._filter_or_exclude(False, args, kwargs)
  File "/Users/raviailani/Documents/envs/lib/python3.9/site-packages/django/db/models/query.py", line 961, in _filter_or_exclude
    clone._filter_or_exclude_inplace(negate, args, kwargs)
  File "/Users/raviailani/Documents/envs/lib/python3.9/site-packages/django/db/models/query.py", line 968, in _filter_or_exclude_inplace
    self._query.add_q(Q(*args, **kwargs))
  File "/Users/raviailani/Documents/envs/lib/python3.9/site-packages/django/db/models/sql/query.py", line 1391, in add_q
    clause, _ = self._add_q(q_object, self.used_aliases)
  File "/Users/raviailani/Documents/envs/lib/python3.9/site-packages/django/db/models/sql/query.py", line 1410, in _add_q
    child_clause, needed_inner = self.build_filter(
  File "/Users/raviailani/Documents/envs/lib/python3.9/site-packages/django/db/models/sql/query.py", line 1345, in build_filter
    condition = self.build_lookup(lookups, col, value)
  File "/Users/raviailani/Documents/envs/lib/python3.9/site-packages/django/db/models/sql/query.py", line 1191, in build_lookup
    lookup = lookup_class(lhs, rhs)
  File "/Users/raviailani/Documents/envs/lib/python3.9/site-packages/django/db/models/lookups.py", line 25, in __init__
    self.rhs = self.get_prep_lookup()
  File "/Users/raviailani/Documents/envs/lib/python3.9/site-packages/django/db/models/lookups.py", line 240, in get_prep_lookup
    rhs_value = self.lhs.output_field.get_prep_value(rhs_value)
  File "/Users/raviailani/Documents/envs/lib/python3.9/site-packages/django/db/models/fields/__init__.py", line 1406, in get_prep_value
    value = super().get_prep_value(value)
  File "/Users/raviailani/Documents/envs/lib/python3.9/site-packages/django/db/models/fields/__init__.py", line 1266, in get_prep_value
    return self.to_python(value)
  File "/Users/raviailani/Documents/envs/lib/python3.9/site-packages/django/db/models/fields/__init__.py", line 1388, in to_python
    raise exceptions.ValidationError(
django.core.exceptions.ValidationError: ['“07/13/2022”的值有一个错误的日期格式。它的格式应该是YYYY-MM-DD HH:MM[:ss[.uuuuuu]][TZ] ']

[2023-04-02 16:51:50,264][dvadmin.utils.exception.CustomExceptionHandler():54] [ERROR] Traceback (most recent call last):
  File "/Users/raviailani/Documents/envs/lib/python3.9/site-packages/rest_framework/views.py", line 506, in dispatch
    response = handler(request, *args, **kwargs)
  File "/Users/raviailani/Documents/envs/lib/python3.9/site-packages/rest_framework/decorators.py", line 50, in handler
    return func(*args, **kwargs)
  File "/Users/raviailani/Documents/django-vue-admin/backend/sensory_data_app/views.py", line 386, in get_data_within_range
    dt = datetime.strptime(start_date, "%Y-%m-%dT%H:%M:%S.%fZ")
TypeError: strptime() argument 1 must be str, not None

[2023-04-02 16:52:05,547][dvadmin.utils.exception.CustomExceptionHandler():54] [ERROR] Traceback (most recent call last):
  File "/Users/raviailani/Documents/envs/lib/python3.9/site-packages/rest_framework/views.py", line 506, in dispatch
    response = handler(request, *args, **kwargs)
  File "/Users/raviailani/Documents/envs/lib/python3.9/site-packages/rest_framework/decorators.py", line 50, in handler
    return func(*args, **kwargs)
  File "/Users/raviailani/Documents/django-vue-admin/backend/sensory_data_app/views.py", line 386, in get_data_within_range
    dt = datetime.strptime(start_date, "%Y-%m-%dT%H:%M:%S.%fZ")
TypeError: strptime() argument 1 must be str, not None

[2023-04-02 16:52:59,684][dvadmin.utils.exception.CustomExceptionHandler():54] [ERROR] Traceback (most recent call last):
  File "/Users/raviailani/Documents/envs/lib/python3.9/site-packages/rest_framework/views.py", line 506, in dispatch
    response = handler(request, *args, **kwargs)
  File "/Users/raviailani/Documents/envs/lib/python3.9/site-packages/rest_framework/decorators.py", line 50, in handler
    return func(*args, **kwargs)
  File "/Users/raviailani/Documents/django-vue-admin/backend/sensory_data_app/views.py", line 386, in get_data_within_range
    dt = datetime.strptime(start_date, "%Y-%m-%dT%H:%M:%S.%fZ")
TypeError: strptime() argument 1 must be str, not None

[2023-04-02 16:54:14,188][dvadmin.utils.exception.CustomExceptionHandler():54] [ERROR] Traceback (most recent call last):
  File "/Users/raviailani/Documents/envs/lib/python3.9/site-packages/rest_framework/views.py", line 506, in dispatch
    response = handler(request, *args, **kwargs)
  File "/Users/raviailani/Documents/envs/lib/python3.9/site-packages/rest_framework/decorators.py", line 50, in handler
    return func(*args, **kwargs)
  File "/Users/raviailani/Documents/django-vue-admin/backend/sensory_data_app/views.py", line 387, in get_data_within_range
    dt = datetime.strptime(start_date, "%Y-%m-%dT%H:%M:%S.%fZ")
TypeError: strptime() argument 1 must be str, not None

[2023-04-02 16:55:41,778][dvadmin.utils.exception.CustomExceptionHandler():54] [ERROR] Traceback (most recent call last):
  File "/Users/raviailani/Documents/envs/lib/python3.9/site-packages/rest_framework/views.py", line 506, in dispatch
    response = handler(request, *args, **kwargs)
  File "/Users/raviailani/Documents/envs/lib/python3.9/site-packages/rest_framework/decorators.py", line 50, in handler
    return func(*args, **kwargs)
  File "/Users/raviailani/Documents/django-vue-admin/backend/sensory_data_app/views.py", line 387, in get_data_within_range
    dt = datetime.strptime(start_date, "%Y-%m-%dT%H:%M:%S.%fZ")
TypeError: strptime() argument 1 must be str, not None

[2023-04-02 16:56:31,503][dvadmin.utils.exception.CustomExceptionHandler():54] [ERROR] Traceback (most recent call last):
  File "/Users/raviailani/Documents/envs/lib/python3.9/site-packages/rest_framework/views.py", line 506, in dispatch
    response = handler(request, *args, **kwargs)
  File "/Users/raviailani/Documents/envs/lib/python3.9/site-packages/rest_framework/decorators.py", line 50, in handler
    return func(*args, **kwargs)
  File "/Users/raviailani/Documents/django-vue-admin/backend/sensory_data_app/views.py", line 387, in get_data_within_range
    dt = datetime.strptime(start_date, "%Y-%m-%dT%H:%M:%S.%fZ")
TypeError: strptime() argument 1 must be str, not None

[2023-04-02 17:05:26,223][dvadmin.utils.exception.CustomExceptionHandler():54] [ERROR] Traceback (most recent call last):
  File "/Users/raviailani/Documents/envs/lib/python3.9/site-packages/django/db/models/fields/__init__.py", line 1378, in to_python
    parsed = parse_date(value)
  File "/Users/raviailani/Documents/envs/lib/python3.9/site-packages/django/utils/dateparse.py", line 78, in parse_date
    return datetime.date(**kw)
ValueError: month must be in 1..12

During handling of the above exception, another exception occurred:

Traceback (most recent call last):
  File "/Users/raviailani/Documents/envs/lib/python3.9/site-packages/rest_framework/views.py", line 506, in dispatch
    response = handler(request, *args, **kwargs)
  File "/Users/raviailani/Documents/envs/lib/python3.9/site-packages/rest_framework/decorators.py", line 50, in handler
    return func(*args, **kwargs)
  File "/Users/raviailani/Documents/django-vue-admin/backend/sensory_data_app/views.py", line 394, in get_data_within_range
    data_queryset = SensoryData.objects.filter(
  File "/Users/raviailani/Documents/envs/lib/python3.9/site-packages/django/db/models/manager.py", line 85, in manager_method
    return getattr(self.get_queryset(), name)(*args, **kwargs)
  File "/Users/raviailani/Documents/envs/lib/python3.9/site-packages/django/db/models/query.py", line 941, in filter
    return self._filter_or_exclude(False, args, kwargs)
  File "/Users/raviailani/Documents/envs/lib/python3.9/site-packages/django/db/models/query.py", line 961, in _filter_or_exclude
    clone._filter_or_exclude_inplace(negate, args, kwargs)
  File "/Users/raviailani/Documents/envs/lib/python3.9/site-packages/django/db/models/query.py", line 968, in _filter_or_exclude_inplace
    self._query.add_q(Q(*args, **kwargs))
  File "/Users/raviailani/Documents/envs/lib/python3.9/site-packages/django/db/models/sql/query.py", line 1391, in add_q
    clause, _ = self._add_q(q_object, self.used_aliases)
  File "/Users/raviailani/Documents/envs/lib/python3.9/site-packages/django/db/models/sql/query.py", line 1410, in _add_q
    child_clause, needed_inner = self.build_filter(
  File "/Users/raviailani/Documents/envs/lib/python3.9/site-packages/django/db/models/sql/query.py", line 1345, in build_filter
    condition = self.build_lookup(lookups, col, value)
  File "/Users/raviailani/Documents/envs/lib/python3.9/site-packages/django/db/models/sql/query.py", line 1191, in build_lookup
    lookup = lookup_class(lhs, rhs)
  File "/Users/raviailani/Documents/envs/lib/python3.9/site-packages/django/db/models/lookups.py", line 25, in __init__
    self.rhs = self.get_prep_lookup()
  File "/Users/raviailani/Documents/envs/lib/python3.9/site-packages/django/db/models/lookups.py", line 240, in get_prep_lookup
    rhs_value = self.lhs.output_field.get_prep_value(rhs_value)
  File "/Users/raviailani/Documents/envs/lib/python3.9/site-packages/django/db/models/fields/__init__.py", line 1406, in get_prep_value
    value = super().get_prep_value(value)
  File "/Users/raviailani/Documents/envs/lib/python3.9/site-packages/django/db/models/fields/__init__.py", line 1266, in get_prep_value
    return self.to_python(value)
  File "/Users/raviailani/Documents/envs/lib/python3.9/site-packages/django/db/models/fields/__init__.py", line 1382, in to_python
    raise exceptions.ValidationError(
django.core.exceptions.ValidationError: ['“2022-18-06”的值有正确的格式（YYYY-MM-DD）但它是一个错误的日期']

[2023-04-02 17:11:43,884][dvadmin.utils.exception.CustomExceptionHandler():54] [ERROR] Traceback (most recent call last):
  File "/Users/raviailani/Documents/envs/lib/python3.9/site-packages/django/db/models/fields/__init__.py", line 1378, in to_python
    parsed = parse_date(value)
  File "/Users/raviailani/Documents/envs/lib/python3.9/site-packages/django/utils/dateparse.py", line 78, in parse_date
    return datetime.date(**kw)
ValueError: month must be in 1..12

During handling of the above exception, another exception occurred:

Traceback (most recent call last):
  File "/Users/raviailani/Documents/envs/lib/python3.9/site-packages/rest_framework/views.py", line 506, in dispatch
    response = handler(request, *args, **kwargs)
  File "/Users/raviailani/Documents/envs/lib/python3.9/site-packages/rest_framework/decorators.py", line 50, in handler
    return func(*args, **kwargs)
  File "/Users/raviailani/Documents/django-vue-admin/backend/sensory_data_app/views.py", line 394, in get_data_within_range
    data = SensoryData.objects.filter(
  File "/Users/raviailani/Documents/envs/lib/python3.9/site-packages/django/db/models/manager.py", line 85, in manager_method
    return getattr(self.get_queryset(), name)(*args, **kwargs)
  File "/Users/raviailani/Documents/envs/lib/python3.9/site-packages/django/db/models/query.py", line 941, in filter
    return self._filter_or_exclude(False, args, kwargs)
  File "/Users/raviailani/Documents/envs/lib/python3.9/site-packages/django/db/models/query.py", line 961, in _filter_or_exclude
    clone._filter_or_exclude_inplace(negate, args, kwargs)
  File "/Users/raviailani/Documents/envs/lib/python3.9/site-packages/django/db/models/query.py", line 968, in _filter_or_exclude_inplace
    self._query.add_q(Q(*args, **kwargs))
  File "/Users/raviailani/Documents/envs/lib/python3.9/site-packages/django/db/models/sql/query.py", line 1391, in add_q
    clause, _ = self._add_q(q_object, self.used_aliases)
  File "/Users/raviailani/Documents/envs/lib/python3.9/site-packages/django/db/models/sql/query.py", line 1410, in _add_q
    child_clause, needed_inner = self.build_filter(
  File "/Users/raviailani/Documents/envs/lib/python3.9/site-packages/django/db/models/sql/query.py", line 1345, in build_filter
    condition = self.build_lookup(lookups, col, value)
  File "/Users/raviailani/Documents/envs/lib/python3.9/site-packages/django/db/models/sql/query.py", line 1191, in build_lookup
    lookup = lookup_class(lhs, rhs)
  File "/Users/raviailani/Documents/envs/lib/python3.9/site-packages/django/db/models/lookups.py", line 25, in __init__
    self.rhs = self.get_prep_lookup()
  File "/Users/raviailani/Documents/envs/lib/python3.9/site-packages/django/db/models/lookups.py", line 240, in get_prep_lookup
    rhs_value = self.lhs.output_field.get_prep_value(rhs_value)
  File "/Users/raviailani/Documents/envs/lib/python3.9/site-packages/django/db/models/fields/__init__.py", line 1406, in get_prep_value
    value = super().get_prep_value(value)
  File "/Users/raviailani/Documents/envs/lib/python3.9/site-packages/django/db/models/fields/__init__.py", line 1266, in get_prep_value
    return self.to_python(value)
  File "/Users/raviailani/Documents/envs/lib/python3.9/site-packages/django/db/models/fields/__init__.py", line 1382, in to_python
    raise exceptions.ValidationError(
django.core.exceptions.ValidationError: ['“2022-16-07”的值有正确的格式（YYYY-MM-DD）但它是一个错误的日期']

[2023-04-02 17:12:37,020][dvadmin.utils.exception.CustomExceptionHandler():54] [ERROR] Traceback (most recent call last):
  File "/Users/raviailani/Documents/envs/lib/python3.9/site-packages/rest_framework/views.py", line 506, in dispatch
    response = handler(request, *args, **kwargs)
  File "/Users/raviailani/Documents/django-vue-admin/backend/dvadmin/utils/viewset.py", line 79, in list
    queryset = self.filter_queryset(self.get_queryset())
  File "/Users/raviailani/Documents/django-vue-admin/backend/dvadmin/utils/viewset.py", line 46, in filter_queryset
    queryset = backend().filter_queryset(self.request, queryset, self)
  File "/Users/raviailani/Documents/django-vue-admin/backend/dvadmin/utils/filters.py", line 305, in filter_queryset
    queryset = queryset.filter(reduce(operator.and_, conditions))
  File "/Users/raviailani/Documents/envs/lib/python3.9/site-packages/django/db/models/query.py", line 941, in filter
    return self._filter_or_exclude(False, args, kwargs)
  File "/Users/raviailani/Documents/envs/lib/python3.9/site-packages/django/db/models/query.py", line 961, in _filter_or_exclude
    clone._filter_or_exclude_inplace(negate, args, kwargs)
  File "/Users/raviailani/Documents/envs/lib/python3.9/site-packages/django/db/models/query.py", line 968, in _filter_or_exclude_inplace
    self._query.add_q(Q(*args, **kwargs))
  File "/Users/raviailani/Documents/envs/lib/python3.9/site-packages/django/db/models/sql/query.py", line 1391, in add_q
    clause, _ = self._add_q(q_object, self.used_aliases)
  File "/Users/raviailani/Documents/envs/lib/python3.9/site-packages/django/db/models/sql/query.py", line 1410, in _add_q
    child_clause, needed_inner = self.build_filter(
  File "/Users/raviailani/Documents/envs/lib/python3.9/site-packages/django/db/models/sql/query.py", line 1263, in build_filter
    return self._add_q(
  File "/Users/raviailani/Documents/envs/lib/python3.9/site-packages/django/db/models/sql/query.py", line 1410, in _add_q
    child_clause, needed_inner = self.build_filter(
  File "/Users/raviailani/Documents/envs/lib/python3.9/site-packages/django/db/models/sql/query.py", line 1345, in build_filter
    condition = self.build_lookup(lookups, col, value)
  File "/Users/raviailani/Documents/envs/lib/python3.9/site-packages/django/db/models/sql/query.py", line 1191, in build_lookup
    lookup = lookup_class(lhs, rhs)
  File "/Users/raviailani/Documents/envs/lib/python3.9/site-packages/django/db/models/lookups.py", line 25, in __init__
    self.rhs = self.get_prep_lookup()
  File "/Users/raviailani/Documents/envs/lib/python3.9/site-packages/django/db/models/lookups.py", line 77, in get_prep_lookup
    return self.lhs.output_field.get_prep_value(self.rhs)
  File "/Users/raviailani/Documents/envs/lib/python3.9/site-packages/django/db/models/fields/__init__.py", line 1406, in get_prep_value
    value = super().get_prep_value(value)
  File "/Users/raviailani/Documents/envs/lib/python3.9/site-packages/django/db/models/fields/__init__.py", line 1266, in get_prep_value
    return self.to_python(value)
  File "/Users/raviailani/Documents/envs/lib/python3.9/site-packages/django/db/models/fields/__init__.py", line 1388, in to_python
    raise exceptions.ValidationError(
django.core.exceptions.ValidationError: ['“”的值有一个错误的日期格式。它的格式应该是YYYY-MM-DD HH:MM[:ss[.uuuuuu]][TZ] ']

[2023-04-02 17:13:47,645][dvadmin.utils.exception.CustomExceptionHandler():54] [ERROR] Traceback (most recent call last):
  File "/Users/raviailani/Documents/envs/lib/python3.9/site-packages/rest_framework/views.py", line 506, in dispatch
    response = handler(request, *args, **kwargs)
  File "/Users/raviailani/Documents/envs/lib/python3.9/site-packages/rest_framework/decorators.py", line 50, in handler
    return func(*args, **kwargs)
  File "/Users/raviailani/Documents/django-vue-admin/backend/sensory_data_app/views.py", line 410, in get_data_within_range
    res += months[i]
NameError: name 'months' is not defined

[2023-04-02 17:22:36,641][dvadmin.utils.exception.CustomExceptionHandler():54] [ERROR] Traceback (most recent call last):
  File "/Users/raviailani/Documents/envs/lib/python3.9/site-packages/rest_framework/views.py", line 506, in dispatch
    response = handler(request, *args, **kwargs)
  File "/Users/raviailani/Documents/envs/lib/python3.9/site-packages/rest_framework/decorators.py", line 50, in handler
    return func(*args, **kwargs)
  File "/Users/raviailani/Documents/django-vue-admin/backend/sensory_data_app/views.py", line 387, in get_data_within_range
    dt =datetime.strptime(start_date, '%Y-%m-%d')
  File "/Users/raviailani/opt/anaconda3/lib/python3.9/_strptime.py", line 568, in _strptime_datetime
    tt, fraction, gmtoff_fraction = _strptime(data_string, format)
  File "/Users/raviailani/opt/anaconda3/lib/python3.9/_strptime.py", line 352, in _strptime
    raise ValueError("unconverted data remains: %s" %
ValueError: unconverted data remains: T05:00:00.000Z

[2023-04-02 17:24:47,248][dvadmin.utils.exception.CustomExceptionHandler():54] [ERROR] Traceback (most recent call last):
  File "/Users/raviailani/Documents/envs/lib/python3.9/site-packages/rest_framework/views.py", line 506, in dispatch
    response = handler(request, *args, **kwargs)
  File "/Users/raviailani/Documents/envs/lib/python3.9/site-packages/rest_framework/decorators.py", line 50, in handler
    return func(*args, **kwargs)
  File "/Users/raviailani/Documents/django-vue-admin/backend/sensory_data_app/views.py", line 425, in get_data_within_range
    return HttpResponse(json.dumps(response), content_type="application/json")
  File "/Users/raviailani/opt/anaconda3/lib/python3.9/json/__init__.py", line 231, in dumps
    return _default_encoder.encode(obj)
  File "/Users/raviailani/opt/anaconda3/lib/python3.9/json/encoder.py", line 199, in encode
    chunks = self.iterencode(o, _one_shot=True)
  File "/Users/raviailani/opt/anaconda3/lib/python3.9/json/encoder.py", line 257, in iterencode
    return _iterencode(o, 0)
  File "/Users/raviailani/opt/anaconda3/lib/python3.9/json/encoder.py", line 179, in default
    raise TypeError(f'Object of type {o.__class__.__name__} '
TypeError: Object of type SensoryData is not JSON serializable

[2023-04-02 17:25:45,861][dvadmin.utils.exception.CustomExceptionHandler():54] [ERROR] Traceback (most recent call last):
  File "/Users/raviailani/Documents/envs/lib/python3.9/site-packages/rest_framework/views.py", line 506, in dispatch
    response = handler(request, *args, **kwargs)
  File "/Users/raviailani/Documents/envs/lib/python3.9/site-packages/rest_framework/decorators.py", line 50, in handler
    return func(*args, **kwargs)
  File "/Users/raviailani/Documents/django-vue-admin/backend/sensory_data_app/views.py", line 426, in get_data_within_range
    return HttpResponse(json.dumps(response), content_type="application/json")
  File "/Users/raviailani/opt/anaconda3/lib/python3.9/json/__init__.py", line 231, in dumps
    return _default_encoder.encode(obj)
  File "/Users/raviailani/opt/anaconda3/lib/python3.9/json/encoder.py", line 199, in encode
    chunks = self.iterencode(o, _one_shot=True)
  File "/Users/raviailani/opt/anaconda3/lib/python3.9/json/encoder.py", line 257, in iterencode
    return _iterencode(o, 0)
  File "/Users/raviailani/opt/anaconda3/lib/python3.9/json/encoder.py", line 179, in default
    raise TypeError(f'Object of type {o.__class__.__name__} '
TypeError: Object of type SensoryData is not JSON serializable

[2023-04-02 17:29:15,537][dvadmin.utils.exception.CustomExceptionHandler():54] [ERROR] Traceback (most recent call last):
  File "/Users/raviailani/Documents/envs/lib/python3.9/site-packages/rest_framework/fields.py", line 457, in get_attribute
    return get_attribute(instance, self.source_attrs)
  File "/Users/raviailani/Documents/envs/lib/python3.9/site-packages/rest_framework/fields.py", line 97, in get_attribute
    instance = getattr(instance, attr)
AttributeError: 'list' object has no attribute 'sea_water_temperature_c'

During handling of the above exception, another exception occurred:

Traceback (most recent call last):
  File "/Users/raviailani/Documents/envs/lib/python3.9/site-packages/rest_framework/views.py", line 506, in dispatch
    response = handler(request, *args, **kwargs)
  File "/Users/raviailani/Documents/envs/lib/python3.9/site-packages/rest_framework/decorators.py", line 50, in handler
    return func(*args, **kwargs)
  File "/Users/raviailani/Documents/django-vue-admin/backend/sensory_data_app/views.py", line 422, in get_data_within_range
    "data": list(data),
  File "/Users/raviailani/Documents/envs/lib/python3.9/site-packages/rest_framework/serializers.py", line 531, in __iter__
    yield self[field.field_name]
  File "/Users/raviailani/Documents/envs/lib/python3.9/site-packages/rest_framework/serializers.py", line 535, in __getitem__
    value = self.data.get(key)
  File "/Users/raviailani/Documents/envs/lib/python3.9/site-packages/rest_framework/serializers.py", line 548, in data
    ret = super().data
  File "/Users/raviailani/Documents/envs/lib/python3.9/site-packages/rest_framework/serializers.py", line 246, in data
    self._data = self.to_representation(self.instance)
  File "/Users/raviailani/Documents/envs/lib/python3.9/site-packages/django_restql/mixins.py", line 149, in to_representation
    return super().to_representation(instance)
  File "/Users/raviailani/Documents/envs/lib/python3.9/site-packages/rest_framework/serializers.py", line 502, in to_representation
    attribute = field.get_attribute(instance)
  File "/Users/raviailani/Documents/envs/lib/python3.9/site-packages/rest_framework/fields.py", line 490, in get_attribute
    raise type(exc)(msg)
AttributeError: Got AttributeError when attempting to get a value for field `sea_water_temperature_c` on serializer `SensoryDataSerializer`.
The serializer field might be named incorrectly and not match any attribute or key on the `list` instance.
Original exception text was: 'list' object has no attribute 'sea_water_temperature_c'.

[2023-04-02 17:33:29,814][dvadmin.utils.exception.CustomExceptionHandler():54] [ERROR] Traceback (most recent call last):
  File "/Users/raviailani/Documents/envs/lib/python3.9/site-packages/rest_framework/views.py", line 506, in dispatch
    response = handler(request, *args, **kwargs)
  File "/Users/raviailani/Documents/envs/lib/python3.9/site-packages/rest_framework/decorators.py", line 50, in handler
    return func(*args, **kwargs)
  File "/Users/raviailani/Documents/django-vue-admin/backend/sensory_data_app/views.py", line 422, in get_data_within_range
    "data": list(data),
TypeError: 'ListSerializer' object is not iterable

[2023-04-02 17:33:48,586][dvadmin.utils.exception.CustomExceptionHandler():54] [ERROR] Traceback (most recent call last):
  File "/Users/raviailani/Documents/envs/lib/python3.9/site-packages/rest_framework/views.py", line 506, in dispatch
    response = handler(request, *args, **kwargs)
  File "/Users/raviailani/Documents/envs/lib/python3.9/site-packages/rest_framework/decorators.py", line 50, in handler
    return func(*args, **kwargs)
  File "/Users/raviailani/Documents/django-vue-admin/backend/sensory_data_app/views.py", line 422, in get_data_within_range
    "data": list(data),
TypeError: 'ListSerializer' object is not iterable

[2023-04-02 17:41:45,061][dvadmin.utils.exception.CustomExceptionHandler():54] [ERROR] Traceback (most recent call last):
  File "/Users/raviailani/Documents/envs/lib/python3.9/site-packages/rest_framework/views.py", line 506, in dispatch
    response = handler(request, *args, **kwargs)
  File "/Users/raviailani/Documents/envs/lib/python3.9/site-packages/rest_framework/decorators.py", line 50, in handler
    return func(*args, **kwargs)
  File "/Users/raviailani/Documents/django-vue-admin/backend/sensory_data_app/views.py", line 432, in get_data_within_range
    return HttpResponse(json.dumps(response), content_type="application/json")
  File "/Users/raviailani/opt/anaconda3/lib/python3.9/json/__init__.py", line 231, in dumps
    return _default_encoder.encode(obj)
  File "/Users/raviailani/opt/anaconda3/lib/python3.9/json/encoder.py", line 199, in encode
    chunks = self.iterencode(o, _one_shot=True)
  File "/Users/raviailani/opt/anaconda3/lib/python3.9/json/encoder.py", line 257, in iterencode
    return _iterencode(o, 0)
  File "/Users/raviailani/opt/anaconda3/lib/python3.9/json/encoder.py", line 179, in default
    raise TypeError(f'Object of type {o.__class__.__name__} '
TypeError: Object of type datetime is not JSON serializable

[2023-04-02 17:42:31,008][dvadmin.utils.exception.CustomExceptionHandler():54] [ERROR] Traceback (most recent call last):
  File "/Users/raviailani/Documents/envs/lib/python3.9/site-packages/rest_framework/views.py", line 506, in dispatch
    response = handler(request, *args, **kwargs)
  File "/Users/raviailani/Documents/envs/lib/python3.9/site-packages/rest_framework/decorators.py", line 50, in handler
    return func(*args, **kwargs)
  File "/Users/raviailani/Documents/django-vue-admin/backend/sensory_data_app/views.py", line 432, in get_data_within_range
    return HttpResponse(json.dumps(response), content_type="application/json")
  File "/Users/raviailani/opt/anaconda3/lib/python3.9/json/__init__.py", line 231, in dumps
    return _default_encoder.encode(obj)
  File "/Users/raviailani/opt/anaconda3/lib/python3.9/json/encoder.py", line 199, in encode
    chunks = self.iterencode(o, _one_shot=True)
  File "/Users/raviailani/opt/anaconda3/lib/python3.9/json/encoder.py", line 257, in iterencode
    return _iterencode(o, 0)
  File "/Users/raviailani/opt/anaconda3/lib/python3.9/json/encoder.py", line 179, in default
    raise TypeError(f'Object of type {o.__class__.__name__} '
TypeError: Object of type datetime is not JSON serializable

[2023-04-02 17:46:09,183][dvadmin.utils.exception.CustomExceptionHandler():54] [ERROR] Traceback (most recent call last):
  File "/Users/raviailani/Documents/envs/lib/python3.9/site-packages/rest_framework/views.py", line 506, in dispatch
    response = handler(request, *args, **kwargs)
  File "/Users/raviailani/Documents/django-vue-admin/backend/dvadmin/utils/import_export_mixin.py", line 303, in export_data
    data = self.export_serializer_class(queryset, many=True, request=request).data
  File "/Users/raviailani/Documents/envs/lib/python3.9/site-packages/rest_framework/serializers.py", line 745, in data
    ret = super().data
  File "/Users/raviailani/Documents/envs/lib/python3.9/site-packages/rest_framework/serializers.py", line 246, in data
    self._data = self.to_representation(self.instance)
  File "/Users/raviailani/Documents/envs/lib/python3.9/site-packages/rest_framework/serializers.py", line 663, in to_representation
    return [
  File "/Users/raviailani/Documents/envs/lib/python3.9/site-packages/django/db/models/query.py", line 280, in __iter__
    self._fetch_all()
  File "/Users/raviailani/Documents/envs/lib/python3.9/site-packages/django/db/models/query.py", line 1324, in _fetch_all
    self._result_cache = list(self._iterable_class(self))
  File "/Users/raviailani/Documents/envs/lib/python3.9/site-packages/django/db/models/query.py", line 51, in __iter__
    results = compiler.execute_sql(chunked_fetch=self.chunked_fetch, chunk_size=self.chunk_size)
  File "/Users/raviailani/Documents/envs/lib/python3.9/site-packages/django/db/models/sql/compiler.py", line 1162, in execute_sql
    sql, params = self.as_sql()
  File "/Users/raviailani/Documents/envs/lib/python3.9/site-packages/django/db/models/sql/compiler.py", line 528, in as_sql
    where, w_params = self.compile(self.where) if self.where is not None else ("", [])
  File "/Users/raviailani/Documents/envs/lib/python3.9/site-packages/django/db/models/sql/compiler.py", line 445, in compile
    sql, params = node.as_sql(self, self.connection)
  File "/Users/raviailani/Documents/envs/lib/python3.9/site-packages/django/db/models/sql/where.py", line 81, in as_sql
    sql, params = compiler.compile(child)
  File "/Users/raviailani/Documents/envs/lib/python3.9/site-packages/django/db/models/sql/compiler.py", line 445, in compile
    sql, params = node.as_sql(self, self.connection)
  File "/Users/raviailani/Documents/envs/lib/python3.9/site-packages/django/db/models/lookups.py", line 315, in as_sql
    return super().as_sql(compiler, connection)
  File "/Users/raviailani/Documents/envs/lib/python3.9/site-packages/django/db/models/lookups.py", line 194, in as_sql
    rhs_sql, rhs_params = self.process_rhs(compiler, connection)
  File "/Users/raviailani/Documents/envs/lib/python3.9/site-packages/django/db/models/lookups.py", line 301, in process_rhs
    return super().process_rhs(compiler, connection)
  File "/Users/raviailani/Documents/envs/lib/python3.9/site-packages/django/db/models/lookups.py", line 101, in process_rhs
    return self.get_db_prep_lookup(value, connection)
  File "/Users/raviailani/Documents/envs/lib/python3.9/site-packages/django/db/models/lookups.py", line 219, in get_db_prep_lookup
    [get_db_prep_value(value, connection, prepared=True)]
  File "/Users/raviailani/Documents/envs/lib/python3.9/site-packages/django/db/models/fields/__init__.py", line 1428, in get_db_prep_value
    return connection.ops.adapt_datetimefield_value(value)
  File "/Users/raviailani/Documents/envs/lib/python3.9/site-packages/django/db/backends/mysql/operations.py", line 250, in adapt_datetimefield_value
    raise ValueError("MySQL backend does not support timezone-aware datetimes when USE_TZ is False.")
ValueError: MySQL backend does not support timezone-aware datetimes when USE_TZ is False.

[2023-04-02 17:48:11,565][dvadmin.utils.exception.CustomExceptionHandler():54] [ERROR] Traceback (most recent call last):
  File "/Users/raviailani/Documents/envs/lib/python3.9/site-packages/rest_framework/views.py", line 506, in dispatch
    response = handler(request, *args, **kwargs)
  File "/Users/raviailani/Documents/django-vue-admin/backend/dvadmin/utils/import_export_mixin.py", line 303, in export_data
    data = self.export_serializer_class(queryset, many=True, request=request).data
  File "/Users/raviailani/Documents/envs/lib/python3.9/site-packages/rest_framework/serializers.py", line 745, in data
    ret = super().data
  File "/Users/raviailani/Documents/envs/lib/python3.9/site-packages/rest_framework/serializers.py", line 246, in data
    self._data = self.to_representation(self.instance)
  File "/Users/raviailani/Documents/envs/lib/python3.9/site-packages/rest_framework/serializers.py", line 663, in to_representation
    return [
  File "/Users/raviailani/Documents/envs/lib/python3.9/site-packages/django/db/models/query.py", line 280, in __iter__
    self._fetch_all()
  File "/Users/raviailani/Documents/envs/lib/python3.9/site-packages/django/db/models/query.py", line 1324, in _fetch_all
    self._result_cache = list(self._iterable_class(self))
  File "/Users/raviailani/Documents/envs/lib/python3.9/site-packages/django/db/models/query.py", line 51, in __iter__
    results = compiler.execute_sql(chunked_fetch=self.chunked_fetch, chunk_size=self.chunk_size)
  File "/Users/raviailani/Documents/envs/lib/python3.9/site-packages/django/db/models/sql/compiler.py", line 1162, in execute_sql
    sql, params = self.as_sql()
  File "/Users/raviailani/Documents/envs/lib/python3.9/site-packages/django/db/models/sql/compiler.py", line 528, in as_sql
    where, w_params = self.compile(self.where) if self.where is not None else ("", [])
  File "/Users/raviailani/Documents/envs/lib/python3.9/site-packages/django/db/models/sql/compiler.py", line 445, in compile
    sql, params = node.as_sql(self, self.connection)
  File "/Users/raviailani/Documents/envs/lib/python3.9/site-packages/django/db/models/sql/where.py", line 81, in as_sql
    sql, params = compiler.compile(child)
  File "/Users/raviailani/Documents/envs/lib/python3.9/site-packages/django/db/models/sql/compiler.py", line 445, in compile
    sql, params = node.as_sql(self, self.connection)
  File "/Users/raviailani/Documents/envs/lib/python3.9/site-packages/django/db/models/lookups.py", line 315, in as_sql
    return super().as_sql(compiler, connection)
  File "/Users/raviailani/Documents/envs/lib/python3.9/site-packages/django/db/models/lookups.py", line 194, in as_sql
    rhs_sql, rhs_params = self.process_rhs(compiler, connection)
  File "/Users/raviailani/Documents/envs/lib/python3.9/site-packages/django/db/models/lookups.py", line 301, in process_rhs
    return super().process_rhs(compiler, connection)
  File "/Users/raviailani/Documents/envs/lib/python3.9/site-packages/django/db/models/lookups.py", line 101, in process_rhs
    return self.get_db_prep_lookup(value, connection)
  File "/Users/raviailani/Documents/envs/lib/python3.9/site-packages/django/db/models/lookups.py", line 219, in get_db_prep_lookup
    [get_db_prep_value(value, connection, prepared=True)]
  File "/Users/raviailani/Documents/envs/lib/python3.9/site-packages/django/db/models/fields/__init__.py", line 1428, in get_db_prep_value
    return connection.ops.adapt_datetimefield_value(value)
  File "/Users/raviailani/Documents/envs/lib/python3.9/site-packages/django/db/backends/mysql/operations.py", line 250, in adapt_datetimefield_value
    raise ValueError("MySQL backend does not support timezone-aware datetimes when USE_TZ is False.")
ValueError: MySQL backend does not support timezone-aware datetimes when USE_TZ is False.

[2023-04-02 17:48:33,333][dvadmin.utils.exception.CustomExceptionHandler():54] [ERROR] Traceback (most recent call last):
  File "/Users/raviailani/Documents/envs/lib/python3.9/site-packages/rest_framework/views.py", line 506, in dispatch
    response = handler(request, *args, **kwargs)
  File "/Users/raviailani/Documents/django-vue-admin/backend/dvadmin/utils/import_export_mixin.py", line 303, in export_data
    data = self.export_serializer_class(queryset, many=True, request=request).data
  File "/Users/raviailani/Documents/envs/lib/python3.9/site-packages/rest_framework/serializers.py", line 745, in data
    ret = super().data
  File "/Users/raviailani/Documents/envs/lib/python3.9/site-packages/rest_framework/serializers.py", line 246, in data
    self._data = self.to_representation(self.instance)
  File "/Users/raviailani/Documents/envs/lib/python3.9/site-packages/rest_framework/serializers.py", line 663, in to_representation
    return [
  File "/Users/raviailani/Documents/envs/lib/python3.9/site-packages/django/db/models/query.py", line 280, in __iter__
    self._fetch_all()
  File "/Users/raviailani/Documents/envs/lib/python3.9/site-packages/django/db/models/query.py", line 1324, in _fetch_all
    self._result_cache = list(self._iterable_class(self))
  File "/Users/raviailani/Documents/envs/lib/python3.9/site-packages/django/db/models/query.py", line 51, in __iter__
    results = compiler.execute_sql(chunked_fetch=self.chunked_fetch, chunk_size=self.chunk_size)
  File "/Users/raviailani/Documents/envs/lib/python3.9/site-packages/django/db/models/sql/compiler.py", line 1162, in execute_sql
    sql, params = self.as_sql()
  File "/Users/raviailani/Documents/envs/lib/python3.9/site-packages/django/db/models/sql/compiler.py", line 528, in as_sql
    where, w_params = self.compile(self.where) if self.where is not None else ("", [])
  File "/Users/raviailani/Documents/envs/lib/python3.9/site-packages/django/db/models/sql/compiler.py", line 445, in compile
    sql, params = node.as_sql(self, self.connection)
  File "/Users/raviailani/Documents/envs/lib/python3.9/site-packages/django/db/models/sql/where.py", line 81, in as_sql
    sql, params = compiler.compile(child)
  File "/Users/raviailani/Documents/envs/lib/python3.9/site-packages/django/db/models/sql/compiler.py", line 445, in compile
    sql, params = node.as_sql(self, self.connection)
  File "/Users/raviailani/Documents/envs/lib/python3.9/site-packages/django/db/models/lookups.py", line 315, in as_sql
    return super().as_sql(compiler, connection)
  File "/Users/raviailani/Documents/envs/lib/python3.9/site-packages/django/db/models/lookups.py", line 194, in as_sql
    rhs_sql, rhs_params = self.process_rhs(compiler, connection)
  File "/Users/raviailani/Documents/envs/lib/python3.9/site-packages/django/db/models/lookups.py", line 301, in process_rhs
    return super().process_rhs(compiler, connection)
  File "/Users/raviailani/Documents/envs/lib/python3.9/site-packages/django/db/models/lookups.py", line 101, in process_rhs
    return self.get_db_prep_lookup(value, connection)
  File "/Users/raviailani/Documents/envs/lib/python3.9/site-packages/django/db/models/lookups.py", line 219, in get_db_prep_lookup
    [get_db_prep_value(value, connection, prepared=True)]
  File "/Users/raviailani/Documents/envs/lib/python3.9/site-packages/django/db/models/fields/__init__.py", line 1428, in get_db_prep_value
    return connection.ops.adapt_datetimefield_value(value)
  File "/Users/raviailani/Documents/envs/lib/python3.9/site-packages/django/db/backends/mysql/operations.py", line 250, in adapt_datetimefield_value
    raise ValueError("MySQL backend does not support timezone-aware datetimes when USE_TZ is False.")
ValueError: MySQL backend does not support timezone-aware datetimes when USE_TZ is False.

[2023-04-03 09:11:34,613][dvadmin.utils.exception.CustomExceptionHandler():54] [ERROR] Traceback (most recent call last):
  File "/Users/raviailani/Documents/envs/lib/python3.9/site-packages/rest_framework/views.py", line 506, in dispatch
    response = handler(request, *args, **kwargs)
  File "/Users/raviailani/Documents/django-vue-admin/backend/dvadmin/utils/import_export_mixin.py", line 303, in export_data
    data = self.export_serializer_class(queryset, many=True, request=request).data
  File "/Users/raviailani/Documents/envs/lib/python3.9/site-packages/rest_framework/serializers.py", line 745, in data
    ret = super().data
  File "/Users/raviailani/Documents/envs/lib/python3.9/site-packages/rest_framework/serializers.py", line 246, in data
    self._data = self.to_representation(self.instance)
  File "/Users/raviailani/Documents/envs/lib/python3.9/site-packages/rest_framework/serializers.py", line 663, in to_representation
    return [
  File "/Users/raviailani/Documents/envs/lib/python3.9/site-packages/django/db/models/query.py", line 280, in __iter__
    self._fetch_all()
  File "/Users/raviailani/Documents/envs/lib/python3.9/site-packages/django/db/models/query.py", line 1324, in _fetch_all
    self._result_cache = list(self._iterable_class(self))
  File "/Users/raviailani/Documents/envs/lib/python3.9/site-packages/django/db/models/query.py", line 51, in __iter__
    results = compiler.execute_sql(chunked_fetch=self.chunked_fetch, chunk_size=self.chunk_size)
  File "/Users/raviailani/Documents/envs/lib/python3.9/site-packages/django/db/models/sql/compiler.py", line 1162, in execute_sql
    sql, params = self.as_sql()
  File "/Users/raviailani/Documents/envs/lib/python3.9/site-packages/django/db/models/sql/compiler.py", line 528, in as_sql
    where, w_params = self.compile(self.where) if self.where is not None else ("", [])
  File "/Users/raviailani/Documents/envs/lib/python3.9/site-packages/django/db/models/sql/compiler.py", line 445, in compile
    sql, params = node.as_sql(self, self.connection)
  File "/Users/raviailani/Documents/envs/lib/python3.9/site-packages/django/db/models/sql/where.py", line 81, in as_sql
    sql, params = compiler.compile(child)
  File "/Users/raviailani/Documents/envs/lib/python3.9/site-packages/django/db/models/sql/compiler.py", line 445, in compile
    sql, params = node.as_sql(self, self.connection)
  File "/Users/raviailani/Documents/envs/lib/python3.9/site-packages/django/db/models/lookups.py", line 315, in as_sql
    return super().as_sql(compiler, connection)
  File "/Users/raviailani/Documents/envs/lib/python3.9/site-packages/django/db/models/lookups.py", line 194, in as_sql
    rhs_sql, rhs_params = self.process_rhs(compiler, connection)
  File "/Users/raviailani/Documents/envs/lib/python3.9/site-packages/django/db/models/lookups.py", line 301, in process_rhs
    return super().process_rhs(compiler, connection)
  File "/Users/raviailani/Documents/envs/lib/python3.9/site-packages/django/db/models/lookups.py", line 101, in process_rhs
    return self.get_db_prep_lookup(value, connection)
  File "/Users/raviailani/Documents/envs/lib/python3.9/site-packages/django/db/models/lookups.py", line 219, in get_db_prep_lookup
    [get_db_prep_value(value, connection, prepared=True)]
  File "/Users/raviailani/Documents/envs/lib/python3.9/site-packages/django/db/models/fields/__init__.py", line 1428, in get_db_prep_value
    return connection.ops.adapt_datetimefield_value(value)
  File "/Users/raviailani/Documents/envs/lib/python3.9/site-packages/django/db/backends/mysql/operations.py", line 250, in adapt_datetimefield_value
    raise ValueError("MySQL backend does not support timezone-aware datetimes when USE_TZ is False.")
ValueError: MySQL backend does not support timezone-aware datetimes when USE_TZ is False.

[2023-04-03 09:12:19,278][dvadmin.utils.exception.CustomExceptionHandler():54] [ERROR] Traceback (most recent call last):
  File "/Users/raviailani/Documents/envs/lib/python3.9/site-packages/rest_framework/views.py", line 506, in dispatch
    response = handler(request, *args, **kwargs)
  File "/Users/raviailani/Documents/django-vue-admin/backend/dvadmin/utils/import_export_mixin.py", line 303, in export_data
    data = self.export_serializer_class(queryset, many=True, request=request).data
  File "/Users/raviailani/Documents/envs/lib/python3.9/site-packages/rest_framework/serializers.py", line 745, in data
    ret = super().data
  File "/Users/raviailani/Documents/envs/lib/python3.9/site-packages/rest_framework/serializers.py", line 246, in data
    self._data = self.to_representation(self.instance)
  File "/Users/raviailani/Documents/envs/lib/python3.9/site-packages/rest_framework/serializers.py", line 663, in to_representation
    return [
  File "/Users/raviailani/Documents/envs/lib/python3.9/site-packages/django/db/models/query.py", line 280, in __iter__
    self._fetch_all()
  File "/Users/raviailani/Documents/envs/lib/python3.9/site-packages/django/db/models/query.py", line 1324, in _fetch_all
    self._result_cache = list(self._iterable_class(self))
  File "/Users/raviailani/Documents/envs/lib/python3.9/site-packages/django/db/models/query.py", line 51, in __iter__
    results = compiler.execute_sql(chunked_fetch=self.chunked_fetch, chunk_size=self.chunk_size)
  File "/Users/raviailani/Documents/envs/lib/python3.9/site-packages/django/db/models/sql/compiler.py", line 1162, in execute_sql
    sql, params = self.as_sql()
  File "/Users/raviailani/Documents/envs/lib/python3.9/site-packages/django/db/models/sql/compiler.py", line 528, in as_sql
    where, w_params = self.compile(self.where) if self.where is not None else ("", [])
  File "/Users/raviailani/Documents/envs/lib/python3.9/site-packages/django/db/models/sql/compiler.py", line 445, in compile
    sql, params = node.as_sql(self, self.connection)
  File "/Users/raviailani/Documents/envs/lib/python3.9/site-packages/django/db/models/sql/where.py", line 81, in as_sql
    sql, params = compiler.compile(child)
  File "/Users/raviailani/Documents/envs/lib/python3.9/site-packages/django/db/models/sql/compiler.py", line 445, in compile
    sql, params = node.as_sql(self, self.connection)
  File "/Users/raviailani/Documents/envs/lib/python3.9/site-packages/django/db/models/lookups.py", line 315, in as_sql
    return super().as_sql(compiler, connection)
  File "/Users/raviailani/Documents/envs/lib/python3.9/site-packages/django/db/models/lookups.py", line 194, in as_sql
    rhs_sql, rhs_params = self.process_rhs(compiler, connection)
  File "/Users/raviailani/Documents/envs/lib/python3.9/site-packages/django/db/models/lookups.py", line 301, in process_rhs
    return super().process_rhs(compiler, connection)
  File "/Users/raviailani/Documents/envs/lib/python3.9/site-packages/django/db/models/lookups.py", line 101, in process_rhs
    return self.get_db_prep_lookup(value, connection)
  File "/Users/raviailani/Documents/envs/lib/python3.9/site-packages/django/db/models/lookups.py", line 219, in get_db_prep_lookup
    [get_db_prep_value(value, connection, prepared=True)]
  File "/Users/raviailani/Documents/envs/lib/python3.9/site-packages/django/db/models/fields/__init__.py", line 1428, in get_db_prep_value
    return connection.ops.adapt_datetimefield_value(value)
  File "/Users/raviailani/Documents/envs/lib/python3.9/site-packages/django/db/backends/mysql/operations.py", line 250, in adapt_datetimefield_value
    raise ValueError("MySQL backend does not support timezone-aware datetimes when USE_TZ is False.")
ValueError: MySQL backend does not support timezone-aware datetimes when USE_TZ is False.

[2023-04-03 09:13:46,650][dvadmin.utils.exception.CustomExceptionHandler():54] [ERROR] Traceback (most recent call last):
  File "/Users/raviailani/Documents/envs/lib/python3.9/site-packages/rest_framework/views.py", line 506, in dispatch
    response = handler(request, *args, **kwargs)
  File "/Users/raviailani/Documents/django-vue-admin/backend/dvadmin/utils/import_export_mixin.py", line 303, in export_data
    data = self.export_serializer_class(queryset, many=True, request=request).data
  File "/Users/raviailani/Documents/envs/lib/python3.9/site-packages/rest_framework/serializers.py", line 745, in data
    ret = super().data
  File "/Users/raviailani/Documents/envs/lib/python3.9/site-packages/rest_framework/serializers.py", line 246, in data
    self._data = self.to_representation(self.instance)
  File "/Users/raviailani/Documents/envs/lib/python3.9/site-packages/rest_framework/serializers.py", line 663, in to_representation
    return [
  File "/Users/raviailani/Documents/envs/lib/python3.9/site-packages/django/db/models/query.py", line 280, in __iter__
    self._fetch_all()
  File "/Users/raviailani/Documents/envs/lib/python3.9/site-packages/django/db/models/query.py", line 1324, in _fetch_all
    self._result_cache = list(self._iterable_class(self))
  File "/Users/raviailani/Documents/envs/lib/python3.9/site-packages/django/db/models/query.py", line 51, in __iter__
    results = compiler.execute_sql(chunked_fetch=self.chunked_fetch, chunk_size=self.chunk_size)
  File "/Users/raviailani/Documents/envs/lib/python3.9/site-packages/django/db/models/sql/compiler.py", line 1162, in execute_sql
    sql, params = self.as_sql()
  File "/Users/raviailani/Documents/envs/lib/python3.9/site-packages/django/db/models/sql/compiler.py", line 528, in as_sql
    where, w_params = self.compile(self.where) if self.where is not None else ("", [])
  File "/Users/raviailani/Documents/envs/lib/python3.9/site-packages/django/db/models/sql/compiler.py", line 445, in compile
    sql, params = node.as_sql(self, self.connection)
  File "/Users/raviailani/Documents/envs/lib/python3.9/site-packages/django/db/models/sql/where.py", line 81, in as_sql
    sql, params = compiler.compile(child)
  File "/Users/raviailani/Documents/envs/lib/python3.9/site-packages/django/db/models/sql/compiler.py", line 445, in compile
    sql, params = node.as_sql(self, self.connection)
  File "/Users/raviailani/Documents/envs/lib/python3.9/site-packages/django/db/models/lookups.py", line 315, in as_sql
    return super().as_sql(compiler, connection)
  File "/Users/raviailani/Documents/envs/lib/python3.9/site-packages/django/db/models/lookups.py", line 194, in as_sql
    rhs_sql, rhs_params = self.process_rhs(compiler, connection)
  File "/Users/raviailani/Documents/envs/lib/python3.9/site-packages/django/db/models/lookups.py", line 301, in process_rhs
    return super().process_rhs(compiler, connection)
  File "/Users/raviailani/Documents/envs/lib/python3.9/site-packages/django/db/models/lookups.py", line 101, in process_rhs
    return self.get_db_prep_lookup(value, connection)
  File "/Users/raviailani/Documents/envs/lib/python3.9/site-packages/django/db/models/lookups.py", line 219, in get_db_prep_lookup
    [get_db_prep_value(value, connection, prepared=True)]
  File "/Users/raviailani/Documents/envs/lib/python3.9/site-packages/django/db/models/fields/__init__.py", line 1428, in get_db_prep_value
    return connection.ops.adapt_datetimefield_value(value)
  File "/Users/raviailani/Documents/envs/lib/python3.9/site-packages/django/db/backends/mysql/operations.py", line 250, in adapt_datetimefield_value
    raise ValueError("MySQL backend does not support timezone-aware datetimes when USE_TZ is False.")
ValueError: MySQL backend does not support timezone-aware datetimes when USE_TZ is False.

[2023-04-03 09:28:09,964][django.request.log_response():224] [ERROR] Internal Server Error: /api/system/sensory_data/export_data_to_excel/
Traceback (most recent call last):
  File "/Users/raviailani/Documents/envs/lib/python3.9/site-packages/asgiref/sync.py", line 472, in thread_handler
    raise exc_info[1]
  File "/Users/raviailani/Documents/envs/lib/python3.9/site-packages/django/core/handlers/exception.py", line 38, in inner
    response = await get_response(request)
  File "/Users/raviailani/Documents/envs/lib/python3.9/site-packages/django/core/handlers/base.py", line 233, in _get_response_async
    response = await wrapped_callback(request, *callback_args, **callback_kwargs)
  File "/Users/raviailani/Documents/envs/lib/python3.9/site-packages/asgiref/sync.py", line 435, in __call__
    ret = await asyncio.wait_for(future, timeout=None)
  File "/Users/raviailani/opt/anaconda3/lib/python3.9/asyncio/tasks.py", line 442, in wait_for
    return await fut
  File "/Users/raviailani/Documents/envs/lib/python3.9/site-packages/asgiref/current_thread_executor.py", line 22, in run
    result = self.fn(*self.args, **self.kwargs)
  File "/Users/raviailani/Documents/envs/lib/python3.9/site-packages/asgiref/sync.py", line 476, in thread_handler
    return func(*args, **kwargs)
  File "/Users/raviailani/Documents/django-vue-admin/backend/sensory_data_app/views.py", line 443, in export_data_to_excel
    dt = datetime.strptime(start_date, "%Y-%m-%dT%H:%M:%S.%fZ")
TypeError: strptime() argument 1 must be str, not None
[2023-04-03 09:28:09,967][django.channels.server.log_action():160] [ERROR] [35;1mHTTP GET /api/system/sensory_data/export_data_to_excel/?date_recorded=2022-04-07T05%3A00%3A00.000Z 500 [0.04, 127.0.0.1:56557][0m
[2023-04-03 09:28:55,970][django.request.log_response():224] [ERROR] Internal Server Error: /api/system/sensory_data/export_data_to_excel/
Traceback (most recent call last):
  File "/Users/raviailani/Documents/envs/lib/python3.9/site-packages/asgiref/sync.py", line 472, in thread_handler
    raise exc_info[1]
  File "/Users/raviailani/Documents/envs/lib/python3.9/site-packages/django/core/handlers/exception.py", line 38, in inner
    response = await get_response(request)
  File "/Users/raviailani/Documents/envs/lib/python3.9/site-packages/django/core/handlers/base.py", line 233, in _get_response_async
    response = await wrapped_callback(request, *callback_args, **callback_kwargs)
  File "/Users/raviailani/Documents/envs/lib/python3.9/site-packages/asgiref/sync.py", line 435, in __call__
    ret = await asyncio.wait_for(future, timeout=None)
  File "/Users/raviailani/opt/anaconda3/lib/python3.9/asyncio/tasks.py", line 442, in wait_for
    return await fut
  File "/Users/raviailani/Documents/envs/lib/python3.9/site-packages/asgiref/current_thread_executor.py", line 22, in run
    result = self.fn(*self.args, **self.kwargs)
  File "/Users/raviailani/Documents/envs/lib/python3.9/site-packages/asgiref/sync.py", line 476, in thread_handler
    return func(*args, **kwargs)
  File "/Users/raviailani/Documents/django-vue-admin/backend/sensory_data_app/views.py", line 469, in export_data_to_excel
    ws.append([row["sea_water_temperature_c"], row['salinity'], row['dissolved_oxygen',row['ph'],row['date_recorded'].strftime('%Y-%m-%d %H:%M:%S')]])
TypeError: 'SensoryData' object is not subscriptable
[2023-04-03 09:28:55,973][django.channels.server.log_action():160] [ERROR] [35;1mHTTP GET /api/system/sensory_data/export_data_to_excel/?date_recorded=2022-04-07T05%3A00%3A00.000Z 500 [0.19, 127.0.0.1:56801][0m
[2023-04-03 09:30:18,312][django.request.log_response():224] [ERROR] Internal Server Error: /api/system/sensory_data/export_data_to_excel/
Traceback (most recent call last):
  File "/Users/raviailani/Documents/envs/lib/python3.9/site-packages/asgiref/sync.py", line 472, in thread_handler
    raise exc_info[1]
  File "/Users/raviailani/Documents/envs/lib/python3.9/site-packages/django/core/handlers/exception.py", line 38, in inner
    response = await get_response(request)
  File "/Users/raviailani/Documents/envs/lib/python3.9/site-packages/django/core/handlers/base.py", line 233, in _get_response_async
    response = await wrapped_callback(request, *callback_args, **callback_kwargs)
  File "/Users/raviailani/Documents/envs/lib/python3.9/site-packages/asgiref/sync.py", line 435, in __call__
    ret = await asyncio.wait_for(future, timeout=None)
  File "/Users/raviailani/opt/anaconda3/lib/python3.9/asyncio/tasks.py", line 442, in wait_for
    return await fut
  File "/Users/raviailani/Documents/envs/lib/python3.9/site-packages/asgiref/current_thread_executor.py", line 22, in run
    result = self.fn(*self.args, **self.kwargs)
  File "/Users/raviailani/Documents/envs/lib/python3.9/site-packages/asgiref/sync.py", line 476, in thread_handler
    return func(*args, **kwargs)
  File "/Users/raviailani/Documents/django-vue-admin/backend/sensory_data_app/views.py", line 469, in export_data_to_excel
    ws.append(row.sea_water_temperature_c, row.salinity, row.dissolved_oxygen,row.ph,row.date_recorded.strftime('%Y-%m-%d %H:%M:%S'))
TypeError: append() takes 2 positional arguments but 6 were given
[2023-04-03 09:30:18,315][django.channels.server.log_action():160] [ERROR] [35;1mHTTP GET /api/system/sensory_data/export_data_to_excel/?date_recorded=2022-04-07T05%3A00%3A00.000Z 500 [0.19, 127.0.0.1:57142][0m
[2023-04-03 09:45:57,871][django.request.log_response():224] [ERROR] Internal Server Error: /api/system/sensory_data/export_data_to_excel/
Traceback (most recent call last):
  File "/Users/raviailani/Documents/envs/lib/python3.9/site-packages/asgiref/sync.py", line 472, in thread_handler
    raise exc_info[1]
  File "/Users/raviailani/Documents/envs/lib/python3.9/site-packages/django/core/handlers/exception.py", line 38, in inner
    response = await get_response(request)
  File "/Users/raviailani/Documents/envs/lib/python3.9/site-packages/django/core/handlers/base.py", line 233, in _get_response_async
    response = await wrapped_callback(request, *callback_args, **callback_kwargs)
  File "/Users/raviailani/Documents/envs/lib/python3.9/site-packages/asgiref/sync.py", line 435, in __call__
    ret = await asyncio.wait_for(future, timeout=None)
  File "/Users/raviailani/opt/anaconda3/lib/python3.9/asyncio/tasks.py", line 442, in wait_for
    return await fut
  File "/Users/raviailani/Documents/envs/lib/python3.9/site-packages/asgiref/current_thread_executor.py", line 22, in run
    result = self.fn(*self.args, **self.kwargs)
  File "/Users/raviailani/Documents/envs/lib/python3.9/site-packages/asgiref/sync.py", line 476, in thread_handler
    return func(*args, **kwargs)
  File "/Users/raviailani/Documents/django-vue-admin/backend/sensory_data_app/views.py", line 443, in export_data_to_excel
    dt = datetime.strptime(start_date, "%Y-%m-%dT%H:%M:%S.%fZ")
TypeError: strptime() argument 1 must be str, not None
[2023-04-03 09:45:57,874][django.channels.server.log_action():160] [ERROR] [35;1mHTTP GET /api/system/sensory_data/export_data_to_excel/ 500 [0.08, 127.0.0.1:60973][0m
[2023-04-03 10:02:00,663][dvadmin.utils.exception.CustomExceptionHandler():54] [ERROR] Traceback (most recent call last):
  File "/Users/raviailani/Documents/envs/lib/python3.9/site-packages/rest_framework/views.py", line 506, in dispatch
    response = handler(request, *args, **kwargs)
  File "/Users/raviailani/Documents/django-vue-admin/backend/dvadmin/utils/viewset.py", line 79, in list
    queryset = self.filter_queryset(self.get_queryset())
  File "/Users/raviailani/Documents/django-vue-admin/backend/dvadmin/utils/viewset.py", line 46, in filter_queryset
    queryset = backend().filter_queryset(self.request, queryset, self)
  File "/Users/raviailani/Documents/django-vue-admin/backend/dvadmin/utils/filters.py", line 305, in filter_queryset
    queryset = queryset.filter(reduce(operator.and_, conditions))
  File "/Users/raviailani/Documents/envs/lib/python3.9/site-packages/django/db/models/query.py", line 941, in filter
    return self._filter_or_exclude(False, args, kwargs)
  File "/Users/raviailani/Documents/envs/lib/python3.9/site-packages/django/db/models/query.py", line 961, in _filter_or_exclude
    clone._filter_or_exclude_inplace(negate, args, kwargs)
  File "/Users/raviailani/Documents/envs/lib/python3.9/site-packages/django/db/models/query.py", line 968, in _filter_or_exclude_inplace
    self._query.add_q(Q(*args, **kwargs))
  File "/Users/raviailani/Documents/envs/lib/python3.9/site-packages/django/db/models/sql/query.py", line 1391, in add_q
    clause, _ = self._add_q(q_object, self.used_aliases)
  File "/Users/raviailani/Documents/envs/lib/python3.9/site-packages/django/db/models/sql/query.py", line 1410, in _add_q
    child_clause, needed_inner = self.build_filter(
  File "/Users/raviailani/Documents/envs/lib/python3.9/site-packages/django/db/models/sql/query.py", line 1263, in build_filter
    return self._add_q(
  File "/Users/raviailani/Documents/envs/lib/python3.9/site-packages/django/db/models/sql/query.py", line 1410, in _add_q
    child_clause, needed_inner = self.build_filter(
  File "/Users/raviailani/Documents/envs/lib/python3.9/site-packages/django/db/models/sql/query.py", line 1345, in build_filter
    condition = self.build_lookup(lookups, col, value)
  File "/Users/raviailani/Documents/envs/lib/python3.9/site-packages/django/db/models/sql/query.py", line 1191, in build_lookup
    lookup = lookup_class(lhs, rhs)
  File "/Users/raviailani/Documents/envs/lib/python3.9/site-packages/django/db/models/lookups.py", line 25, in __init__
    self.rhs = self.get_prep_lookup()
  File "/Users/raviailani/Documents/envs/lib/python3.9/site-packages/django/db/models/lookups.py", line 77, in get_prep_lookup
    return self.lhs.output_field.get_prep_value(self.rhs)
  File "/Users/raviailani/Documents/envs/lib/python3.9/site-packages/django/db/models/fields/__init__.py", line 1406, in get_prep_value
    value = super().get_prep_value(value)
  File "/Users/raviailani/Documents/envs/lib/python3.9/site-packages/django/db/models/fields/__init__.py", line 1266, in get_prep_value
    return self.to_python(value)
  File "/Users/raviailani/Documents/envs/lib/python3.9/site-packages/django/db/models/fields/__init__.py", line 1388, in to_python
    raise exceptions.ValidationError(
django.core.exceptions.ValidationError: ['“”的值有一个错误的日期格式。它的格式应该是YYYY-MM-DD HH:MM[:ss[.uuuuuu]][TZ] ']

[2023-04-03 10:10:42,162][django.request.log_response():224] [ERROR] Internal Server Error: /api/system/sensory_data/export_data_to_excel/
Traceback (most recent call last):
  File "/Users/raviailani/Documents/envs/lib/python3.9/site-packages/asgiref/sync.py", line 472, in thread_handler
    raise exc_info[1]
  File "/Users/raviailani/Documents/envs/lib/python3.9/site-packages/django/core/handlers/exception.py", line 38, in inner
    response = await get_response(request)
  File "/Users/raviailani/Documents/envs/lib/python3.9/site-packages/django/core/handlers/base.py", line 233, in _get_response_async
    response = await wrapped_callback(request, *callback_args, **callback_kwargs)
  File "/Users/raviailani/Documents/envs/lib/python3.9/site-packages/asgiref/sync.py", line 435, in __call__
    ret = await asyncio.wait_for(future, timeout=None)
  File "/Users/raviailani/opt/anaconda3/lib/python3.9/asyncio/tasks.py", line 442, in wait_for
    return await fut
  File "/Users/raviailani/Documents/envs/lib/python3.9/site-packages/asgiref/current_thread_executor.py", line 22, in run
    result = self.fn(*self.args, **self.kwargs)
  File "/Users/raviailani/Documents/envs/lib/python3.9/site-packages/asgiref/sync.py", line 476, in thread_handler
    return func(*args, **kwargs)
  File "/Users/raviailani/Documents/django-vue-admin/backend/sensory_data_app/views.py", line 455, in export_data_to_excel
    date_recorded__range=(start_date, end_date)
NameError: name 'end_date' is not defined
[2023-04-03 10:10:42,166][django.channels.server.log_action():160] [ERROR] [35;1mHTTP GET /api/system/sensory_data/export_data_to_excel/?date_recorded=2022-04-01T05%3A00%3A00.000Z&end_date=2022-04-05T05%3A00%3A00.000Z 500 [0.10, 127.0.0.1:64433][0m
[2023-04-18 13:38:27,998][dvadmin.utils.exception.CustomExceptionHandler():54] [ERROR] Traceback (most recent call last):
  File "/Users/raviailani/Documents/envs/lib/python3.9/site-packages/rest_framework/views.py", line 506, in dispatch
    response = handler(request, *args, **kwargs)
  File "/Users/raviailani/Documents/envs/lib/python3.9/site-packages/rest_framework/decorators.py", line 50, in handler
    return func(*args, **kwargs)
  File "/Users/raviailani/Documents/django-vue-admin/backend/sensory_data_app/views.py", line 501, in get_plain_line_chart_data
    return HttpResponse(json.dumps(res), content_type="application/json")
  File "/Users/raviailani/opt/anaconda3/lib/python3.9/json/__init__.py", line 231, in dumps
    return _default_encoder.encode(obj)
  File "/Users/raviailani/opt/anaconda3/lib/python3.9/json/encoder.py", line 199, in encode
    chunks = self.iterencode(o, _one_shot=True)
  File "/Users/raviailani/opt/anaconda3/lib/python3.9/json/encoder.py", line 257, in iterencode
    return _iterencode(o, 0)
  File "/Users/raviailani/opt/anaconda3/lib/python3.9/json/encoder.py", line 179, in default
    raise TypeError(f'Object of type {o.__class__.__name__} '
TypeError: Object of type datetime is not JSON serializable

[2023-04-18 13:38:29,350][dvadmin.utils.exception.CustomExceptionHandler():54] [ERROR] Traceback (most recent call last):
  File "/Users/raviailani/Documents/envs/lib/python3.9/site-packages/rest_framework/views.py", line 506, in dispatch
    response = handler(request, *args, **kwargs)
  File "/Users/raviailani/Documents/envs/lib/python3.9/site-packages/rest_framework/decorators.py", line 50, in handler
    return func(*args, **kwargs)
  File "/Users/raviailani/Documents/django-vue-admin/backend/sensory_data_app/views.py", line 501, in get_plain_line_chart_data
    return HttpResponse(json.dumps(res), content_type="application/json")
  File "/Users/raviailani/opt/anaconda3/lib/python3.9/json/__init__.py", line 231, in dumps
    return _default_encoder.encode(obj)
  File "/Users/raviailani/opt/anaconda3/lib/python3.9/json/encoder.py", line 199, in encode
    chunks = self.iterencode(o, _one_shot=True)
  File "/Users/raviailani/opt/anaconda3/lib/python3.9/json/encoder.py", line 257, in iterencode
    return _iterencode(o, 0)
  File "/Users/raviailani/opt/anaconda3/lib/python3.9/json/encoder.py", line 179, in default
    raise TypeError(f'Object of type {o.__class__.__name__} '
TypeError: Object of type datetime is not JSON serializable

[2023-04-18 13:38:30,635][dvadmin.utils.exception.CustomExceptionHandler():54] [ERROR] Traceback (most recent call last):
  File "/Users/raviailani/Documents/envs/lib/python3.9/site-packages/rest_framework/views.py", line 506, in dispatch
    response = handler(request, *args, **kwargs)
  File "/Users/raviailani/Documents/envs/lib/python3.9/site-packages/rest_framework/decorators.py", line 50, in handler
    return func(*args, **kwargs)
  File "/Users/raviailani/Documents/django-vue-admin/backend/sensory_data_app/views.py", line 501, in get_plain_line_chart_data
    return HttpResponse(json.dumps(res), content_type="application/json")
  File "/Users/raviailani/opt/anaconda3/lib/python3.9/json/__init__.py", line 231, in dumps
    return _default_encoder.encode(obj)
  File "/Users/raviailani/opt/anaconda3/lib/python3.9/json/encoder.py", line 199, in encode
    chunks = self.iterencode(o, _one_shot=True)
  File "/Users/raviailani/opt/anaconda3/lib/python3.9/json/encoder.py", line 257, in iterencode
    return _iterencode(o, 0)
  File "/Users/raviailani/opt/anaconda3/lib/python3.9/json/encoder.py", line 179, in default
    raise TypeError(f'Object of type {o.__class__.__name__} '
TypeError: Object of type datetime is not JSON serializable

[2023-04-18 13:38:31,972][dvadmin.utils.exception.CustomExceptionHandler():54] [ERROR] Traceback (most recent call last):
  File "/Users/raviailani/Documents/envs/lib/python3.9/site-packages/rest_framework/views.py", line 506, in dispatch
    response = handler(request, *args, **kwargs)
  File "/Users/raviailani/Documents/envs/lib/python3.9/site-packages/rest_framework/decorators.py", line 50, in handler
    return func(*args, **kwargs)
  File "/Users/raviailani/Documents/django-vue-admin/backend/sensory_data_app/views.py", line 501, in get_plain_line_chart_data
    return HttpResponse(json.dumps(res), content_type="application/json")
  File "/Users/raviailani/opt/anaconda3/lib/python3.9/json/__init__.py", line 231, in dumps
    return _default_encoder.encode(obj)
  File "/Users/raviailani/opt/anaconda3/lib/python3.9/json/encoder.py", line 199, in encode
    chunks = self.iterencode(o, _one_shot=True)
  File "/Users/raviailani/opt/anaconda3/lib/python3.9/json/encoder.py", line 257, in iterencode
    return _iterencode(o, 0)
  File "/Users/raviailani/opt/anaconda3/lib/python3.9/json/encoder.py", line 179, in default
    raise TypeError(f'Object of type {o.__class__.__name__} '
TypeError: Object of type datetime is not JSON serializable

[2023-04-27 10:54:43,185][dvadmin.utils.exception.CustomExceptionHandler():54] [ERROR] Traceback (most recent call last):
  File "/Users/raviailani/Documents/envs/lib/python3.9/site-packages/rest_framework/views.py", line 506, in dispatch
    response = handler(request, *args, **kwargs)
  File "/Users/raviailani/Documents/django-vue-admin/backend/dvadmin/utils/viewset.py", line 75, in create
    self.perform_create(serializer)
  File "/Users/raviailani/Documents/envs/lib/python3.9/site-packages/rest_framework/mixins.py", line 24, in perform_create
    serializer.save()
  File "/Users/raviailani/Documents/django-vue-admin/backend/dvadmin/system/views/message_center.py", line 129, in save
    users = Users.objects.exclude(is_deleted=True).values_list('id', flat=True)
  File "/Users/raviailani/Documents/envs/lib/python3.9/site-packages/django/db/models/manager.py", line 85, in manager_method
    return getattr(self.get_queryset(), name)(*args, **kwargs)
  File "/Users/raviailani/Documents/envs/lib/python3.9/site-packages/django/db/models/query.py", line 949, in exclude
    return self._filter_or_exclude(True, args, kwargs)
  File "/Users/raviailani/Documents/envs/lib/python3.9/site-packages/django/db/models/query.py", line 961, in _filter_or_exclude
    clone._filter_or_exclude_inplace(negate, args, kwargs)
  File "/Users/raviailani/Documents/envs/lib/python3.9/site-packages/django/db/models/query.py", line 966, in _filter_or_exclude_inplace
    self._query.add_q(~Q(*args, **kwargs))
  File "/Users/raviailani/Documents/envs/lib/python3.9/site-packages/django/db/models/sql/query.py", line 1391, in add_q
    clause, _ = self._add_q(q_object, self.used_aliases)
  File "/Users/raviailani/Documents/envs/lib/python3.9/site-packages/django/db/models/sql/query.py", line 1410, in _add_q
    child_clause, needed_inner = self.build_filter(
  File "/Users/raviailani/Documents/envs/lib/python3.9/site-packages/django/db/models/sql/query.py", line 1284, in build_filter
    lookups, parts, reffed_expression = self.solve_lookup_type(arg)
  File "/Users/raviailani/Documents/envs/lib/python3.9/site-packages/django/db/models/sql/query.py", line 1110, in solve_lookup_type
    _, field, _, lookup_parts = self.names_to_path(lookup_splitted, self.get_meta())
  File "/Users/raviailani/Documents/envs/lib/python3.9/site-packages/django/db/models/sql/query.py", line 1537, in names_to_path
    raise FieldError("Cannot resolve keyword '%s' into field. "
django.core.exceptions.FieldError: Cannot resolve keyword 'is_deleted' into field. Choices are: avatar, create_datetime, creator, creator_id, creator_query, date_joined, dept, dept_belong_id, dept_id, description, email, first_name, gender, groups, id, is_active, is_staff, is_superuser, last_login, last_name, mobile, modifier, name, password, post, role, target_user, update_datetime, user, user_permissions, user_type, username

[2023-05-04 14:01:13,600][dvadmin.utils.exception.CustomExceptionHandler():54] [ERROR] Traceback (most recent call last):
  File "/Users/raviailani/Documents/envs/lib/python3.9/site-packages/rest_framework/views.py", line 506, in dispatch
    response = handler(request, *args, **kwargs)
  File "/Users/raviailani/Documents/envs/lib/python3.9/site-packages/rest_framework/decorators.py", line 50, in handler
    return func(*args, **kwargs)
  File "/Users/raviailani/Documents/django-vue-admin/backend/sensory_data_app/views.py", line 573, in get_sensory_violation_data
    return HttpResponse(json.dumps(data), content_type="application/json")
  File "/Users/raviailani/opt/anaconda3/lib/python3.9/json/__init__.py", line 231, in dumps
    return _default_encoder.encode(obj)
  File "/Users/raviailani/opt/anaconda3/lib/python3.9/json/encoder.py", line 199, in encode
    chunks = self.iterencode(o, _one_shot=True)
  File "/Users/raviailani/opt/anaconda3/lib/python3.9/json/encoder.py", line 257, in iterencode
    return _iterencode(o, 0)
  File "/Users/raviailani/opt/anaconda3/lib/python3.9/json/encoder.py", line 179, in default
    raise TypeError(f'Object of type {o.__class__.__name__} '
TypeError: Object of type QuerySet is not JSON serializable

[2023-05-04 14:02:09,110][dvadmin.utils.exception.CustomExceptionHandler():54] [ERROR] Traceback (most recent call last):
  File "/Users/raviailani/Documents/envs/lib/python3.9/site-packages/rest_framework/views.py", line 506, in dispatch
    response = handler(request, *args, **kwargs)
  File "/Users/raviailani/Documents/envs/lib/python3.9/site-packages/rest_framework/decorators.py", line 50, in handler
    return func(*args, **kwargs)
  File "/Users/raviailani/Documents/django-vue-admin/backend/sensory_data_app/views.py", line 573, in get_sensory_violation_data
    return HttpResponse(json.dumps(data), content_type="application/json")
  File "/Users/raviailani/opt/anaconda3/lib/python3.9/json/__init__.py", line 231, in dumps
    return _default_encoder.encode(obj)
  File "/Users/raviailani/opt/anaconda3/lib/python3.9/json/encoder.py", line 199, in encode
    chunks = self.iterencode(o, _one_shot=True)
  File "/Users/raviailani/opt/anaconda3/lib/python3.9/json/encoder.py", line 257, in iterencode
    return _iterencode(o, 0)
  File "/Users/raviailani/opt/anaconda3/lib/python3.9/json/encoder.py", line 179, in default
    raise TypeError(f'Object of type {o.__class__.__name__} '
TypeError: Object of type QuerySet is not JSON serializable

[2023-05-04 14:02:34,928][dvadmin.utils.exception.CustomExceptionHandler():54] [ERROR] Traceback (most recent call last):
  File "/Users/raviailani/Documents/envs/lib/python3.9/site-packages/rest_framework/views.py", line 506, in dispatch
    response = handler(request, *args, **kwargs)
  File "/Users/raviailani/Documents/envs/lib/python3.9/site-packages/rest_framework/decorators.py", line 50, in handler
    return func(*args, **kwargs)
  File "/Users/raviailani/Documents/django-vue-admin/backend/sensory_data_app/views.py", line 572, in get_sensory_violation_data
    print(data[0]["date_recorded"])
TypeError: 'SensoryData' object is not subscriptable

[2023-05-04 14:05:01,361][dvadmin.utils.exception.CustomExceptionHandler():54] [ERROR] Traceback (most recent call last):
  File "/Users/raviailani/Documents/envs/lib/python3.9/site-packages/rest_framework/views.py", line 506, in dispatch
    response = handler(request, *args, **kwargs)
  File "/Users/raviailani/Documents/envs/lib/python3.9/site-packages/rest_framework/decorators.py", line 50, in handler
    return func(*args, **kwargs)
  File "/Users/raviailani/Documents/django-vue-admin/backend/sensory_data_app/views.py", line 576, in get_sensory_violation_data
    obj = record["date_recorded"]
TypeError: 'SensoryData' object is not subscriptable

[2023-05-04 14:05:29,761][dvadmin.utils.exception.CustomExceptionHandler():54] [ERROR] Traceback (most recent call last):
  File "/Users/raviailani/Documents/envs/lib/python3.9/site-packages/rest_framework/views.py", line 506, in dispatch
    response = handler(request, *args, **kwargs)
  File "/Users/raviailani/Documents/envs/lib/python3.9/site-packages/rest_framework/decorators.py", line 50, in handler
    return func(*args, **kwargs)
  File "/Users/raviailani/Documents/django-vue-admin/backend/sensory_data_app/views.py", line 583, in get_sensory_violation_data
    obj["sea_water_temperature_c"] = record["sea_water_temperature_c"]
TypeError: 'SensoryData' object is not subscriptable

[2023-05-04 14:05:50,441][dvadmin.utils.exception.CustomExceptionHandler():54] [ERROR] Traceback (most recent call last):
  File "/Users/raviailani/Documents/envs/lib/python3.9/site-packages/rest_framework/views.py", line 506, in dispatch
    response = handler(request, *args, **kwargs)
  File "/Users/raviailani/Documents/envs/lib/python3.9/site-packages/rest_framework/decorators.py", line 50, in handler
    return func(*args, **kwargs)
  File "/Users/raviailani/Documents/django-vue-admin/backend/sensory_data_app/views.py", line 583, in get_sensory_violation_data
    obj["sea_water_temperature_c"] = record["sea_water_temperature_c"]
TypeError: 'SensoryData' object is not subscriptable

[2023-05-04 14:06:03,068][dvadmin.utils.exception.CustomExceptionHandler():54] [ERROR] Traceback (most recent call last):
  File "/Users/raviailani/Documents/envs/lib/python3.9/site-packages/rest_framework/views.py", line 506, in dispatch
    response = handler(request, *args, **kwargs)
  File "/Users/raviailani/Documents/envs/lib/python3.9/site-packages/rest_framework/decorators.py", line 50, in handler
    return func(*args, **kwargs)
  File "/Users/raviailani/Documents/django-vue-admin/backend/sensory_data_app/views.py", line 583, in get_sensory_violation_data
    obj["sea_water_temperature_c"] = record["sea_water_temperature_c"]
TypeError: 'SensoryData' object is not subscriptable

